Workbook
Name cFB: #REF!
Name cFB: #REF!
Name coCORE: #REF!
Name coCORE: #REF!
Name coSW1: #REF!
Name coSW1: #REF!
Name coSW2: #REF!
Name coSW2: #REF!
Name cSW250_: #REF!
Name cSW250_: #REF!
Name G3coSW2: #REF!
Name G3coSW2: #REF!

Sheet Summary
B2: Aquitic Invertebrate Data
B3: NCOS, COPR, and Vernal Pools
B4: 2018 -2019
B6: General: | C6: The TABS progress from the log entry order to being sorted by data type and NORMALIZED which is YELLOW. This is followed by progressions for SALINITY and SITE, eaching ending with a YELLOW summary tab. Finally, the 2018-2019 Shannon-Wiener tab is also YELLOW. This was mainly done to progressively get the data into a format facilitating semi-automatic graphing - thus introducing fewer errors.
B10: Sampling Protocols
B12: General: Samples were taken in, or as near as possible to, algae or other vegetation at a given site. This was due to the observation that invertebrates were significantly more abundant there (nominally, 30x more) than in open water. FB250 (Filtered Beaker, 250 micron mesh) was the prefered sampling technique as it allowed easier sampling within the algae and a more accurate determination of sample size.
B16: FB250 Using a 500ml cup, water was collected at varying levels up to a 50cm depth and placed into a 7.5 liter bucket. When full, the bucket was poured through the 250 micron filter. The contents of the filter were then washed into a 150ml vial using 70% isopropyl alcohol. To get the normalized population density in bugs/liter, one needs to divide the number of bugs by the 7.5 liter sample size.
B20: SW1 A D-shaped sweep net with a nominal face-area of 640 cm2 utilizing seven 'standard' sweeps of one-meter length or one continuous sweep of seven meters was used. If the net were fully submerged, then 448 liters would have been sampled. As it was often impossible to fully submerge the sweep net, due to the shallowness of the pool, there was no consistent volume of water sampled and, therefore, it is difficult to more than roughly estimate the normalized population density. In other words, if we collected twice as many bugs at site A than at Site B, was it because site A was twice as deep and therefore we sampled twice as much water than we did at site B or was the density of bugs at site A twice as high?
B26: CORE A five-centimeter diameter PVC pipe was pushed five centimeters into the benthic floor of the site and the soil removed as a plug, 0.091 liters in volume. This was then dissolved in a bucket of water by massaging it with our fingers. The resultant effluent was then poured through the 250 micron filter and the contents washed into a 150ml vial using 70% isopropyl alcohol. To get the normalized population density in bugs/liter, one needs to divide the number of bugs found by 0.091 (or multiply by 10.98).
B31: Site Names
R43: Note that on this representation the NCOS vernal pools
R44: are called NVP2 and NVP4 because the emphasis in on their being in NCOS
R45: In the representation below, the are called
R46: VNVP2 and VNVP4 as the emphasis is that they are Vernal Pools
R47: This was done to make it easier to sort them in Excel.
R48: In reality, it would have been better to also put a 'C' in front of the COPR sites as well.
Q64: Vernal Pool Locations

Sheet 2019 Data by Date
A1: Date | B1: Site | C1: Sample Type | E1: Ostracod | F1: Copepod | G1: Hemiptera: Corixidae (boatman) | H1: Cladocera | I1: Nematode | J1: Diptera - TOTAL | K1: Dipteran sp. | L1: Diptera: Chironomid | M1: Diptera: Ceratopogonidae | N1: Diptera: Culicidae | O1: Diptera: Ephydridae | P1: Diptera: Stratiomyidae | Q1: Amphipod | R1: Hemiptera TOTAL | S1: Hemiptera-Notonectidae | T1: Annelida TOTAL | U1: Annelida Sp. | V1: Annelida: Oligochaete | W1: Annelida: Polychaete | X1: Ephemeroptera Sp. | Y1: Odonate | Z1: Coleoptera - TOTAL | AA1: Coleoptera sp. | AB1: Coleoptera: Dytiscidae | AC1: Coleoptera: Dytiscidae: Liodessus affinis | AD1: Coleoptera: Dytiscidae: Agabus | AE1: Coleoptera: Dytiscidae: Colymbetinae | AF1: Coleoptera: Curculionidae (Weavil) | AG1: Coleoptera - Hydrophilidae | AH1: Coleoperta Hydraenidae | AI1: Coleoptera- Gyrindae- Gyrinini | AJ1: Tipulidae Larva | AK1: Arachnida: Acari (mite) | AL1: Trichoptera Sp. | AM1: Collembola (Springtail) | AN1: Gastropod - snail | AO1: Clam Shrimp | AP1: Total # | AR1: Date | AS1: Time | AT1: Site | AU1: WQ Measurement Depth (cm) | AV1: Sample Type | AW1: Dissolved Oxygen (mg/L) | AX1: Dissolved Oxygen (%) | AY1: Conductivity-specific (mS/cm) | AZ1: Salinity (ppt) | BA1: Temperature (C) | BB1: AtmosphPressure (mmHg) | BC1: pH | BD1: No. Tadpoles | BE1: No. Fish | BF1: Sampled Width (m) | BG1: Max Invertebrate Sampled Depth (m) | BH1: Comments
A2: 43489 | B2: MO1 | C2: FB250 | E2: 2 | F2: 2 | G2: 0 | H2: 1 | I2: 0 | J2: =P2+O2+N2+M2+L2+K2 -> 0 | K2: 0 | L2: 0 | M2: 0 | N2: 0 | O2: 0 | P2: 0 | Q2: 0 | R2: =G2+S2 -> 0 | S2: 0 | T2: =U2+V2+W2 -> 0 | U2: 0 | V2: 0 | W2: 0 | X2: 0 | Y2: 0 | Z2: =SUM(AA2:AI2) -> 0 | AA2: 0 | AB2: 0 | AC2: 0 | AD2: 0 | AE2: 0 | AF2: 0 | AG2: 0 | AH2: 0 | AI2: 0 | AJ2: 0 | AK2: 0 | AL2: 0 | AM2: 0 | AN2: 0 | AO2: 0 | AP2: =SUM(E2:AO2)-Z2-J2-T2-R2 -> 5 | AR2: 43489 | AS2: 0.51041667 | AT2: MO1 | AU2: 10 | AV2: YSI 2030 | AW2: 8.6 | AX2: 96.6 | AY2: 19.32 | AZ2: 23.2 | BA2: 16.3 | BB2: 764.7 | BC2: 8.2
A3: 43492 | B3: VWCB6 | C3: CORE | E3: 2 | F3: 0 | G3: 0 | H3: 0 | I3: 94 | J3: =P3+O3+N3+M3+L3+K3 -> 0 | K3: 0 | L3: 0 | M3: 0 | N3: 0 | O3: 0 | P3: 0 | Q3: 0 | R3: =G3+S3 -> 0 | S3: 0 | T3: =U3+V3+W3 -> 0 | U3: 0 | V3: 0 | W3: 0 | X3: 0 | Y3: 0 | Z3: =SUM(AA3:AI3) -> 0 | AA3: 0 | AB3: 0 | AC3: 0 | AD3: 0 | AE3: 0 | AF3: 0 | AG3: 0 | AH3: 0 | AI3: 0 | AJ3: 0 | AK3: 0 | AL3: 0 | AM3: 0 | AN3: 0 | AO3: 0 | AP3: =SUM(E3:AO3)-Z3-J3-T3-R3 -> 96 | AR3: 43492 | AS3: 0.60416667 | AT3: VWCB6 | AU3: 10 | AV3: YSI 2030 | AW3: 9.74 | AX3: 109.4 | AY3: 0.168 | AZ3: 0.1 | BA3: 21.2 | BB3: 762 | BC3: 8.32 | BD3: 13 | BE3: 0 | BF3: 14 | BG3: 0.33
A4: 43492 | B4: VWCB6 | C4: FB250 | E4: 43 | F4: 143 | G4: 0 | H4: 166 | I4: 0 | J4: =P4+O4+N4+M4+L4+K4 -> 2 | K4: 0 | L4: 2 | M4: 0 | N4: 0 | O4: 0 | P4: 0 | Q4: 0 | R4: =G4+S4 -> 0 | S4: 0 | T4: =U4+V4+W4 -> 0 | U4: 0 | V4: 0 | W4: 0 | X4: 0 | Y4: 0 | Z4: =SUM(AA4:AI4) -> 0 | AA4: 0 | AB4: 0 | AC4: 0 | AD4: 0 | AE4: 0 | AF4: 0 | AG4: 0 | AH4: 0 | AI4: 0 | AJ4: 0 | AK4: 0 | AL4: 0 | AM4: 0 | AN4: 0 | AO4: 0 | AP4: =SUM(E4:AO4)-Z4-J4-T4-R4 -> 354 | AR4: 43492 | AS4: 0.60416667 | AT4: VWCB6 | AU4: 10 | AV4: YSI 2030 | AW4: 9.74 | AX4: 109.4 | AY4: 0.168 | AZ4: 0.1 | BA4: 21.2 | BB4: 762 | BC4: 8.32 | BD4: 13 | BE4: 0 | BF4: 14 | BG4: 0.33
A5: 43492 | B5: VWCB6 | C5: SW1 | E5: 25 | F5: 10 | G5: 0 | H5: 571 | I5: 7 | J5: =P5+O5+N5+M5+L5+K5 -> 2 | K5: 0 | L5: 1 | M5: 1 | N5: 0 | O5: 0 | P5: 0 | Q5: 0 | R5: =G5+S5 -> 0 | S5: 0 | T5: =U5+V5+W5 -> 0 | U5: 0 | V5: 0 | W5: 0 | X5: 0 | Y5: 0 | Z5: =SUM(AA5:AI5) -> 0 | AA5: 0 | AB5: 0 | AC5: 0 | AD5: 0 | AE5: 0 | AF5: 0 | AG5: 0 | AH5: 0 | AI5: 0 | AJ5: 0 | AK5: 0 | AL5: 0 | AM5: 0 | AN5: 0 | AO5: 0 | AP5: =SUM(E5:AO5)-Z5-J5-T5-R5 -> 615 | AR5: 43492 | AS5: 0.60416667 | AT5: VWCB6 | AU5: 10 | AV5: YSI 2030 | AW5: 9.74 | AX5: 109.4 | AY5: 0.168 | AZ5: 0.1 | BA5: 21.2 | BB5: 762 | BC5: 8.32 | BD5: 13 | BE5: 0 | BF5: 14 | BG5: 0.33
A6: 43492 | B6: VDSN | C6: CORE | E6: 0 | F6: 0 | G6: 0 | H6: 1 | I6: 0 | J6: =P6+O6+N6+M6+L6+K6 -> 0 | K6: 0 | L6: 0 | M6: 0 | N6: 0 | O6: 0 | P6: 0 | Q6: 0 | R6: =G6+S6 -> 0 | S6: 0 | T6: =U6+V6+W6 -> 0 | U6: 0 | V6: 0 | W6: 0 | X6: 0 | Y6: 0 | Z6: =SUM(AA6:AI6) -> 0 | AA6: 0 | AB6: 0 | AC6: 0 | AD6: 0 | AE6: 0 | AF6: 0 | AG6: 0 | AH6: 0 | AI6: 0 | AJ6: 0 | AK6: 0 | AL6: 0 | AM6: 0 | AN6: 0 | AO6: 0 | AP6: =SUM(E6:AO6)-Z6-J6-T6-R6 -> 1 | AR6: 43492 | AS6: 0.65972222 | AT6: VDSN | AU6: 10 | AV6: YSI 2030 | AW6: 15.76 | AX6: 182.8 | AY6: 0.2043 | AZ6: 0.1 | BA6: 22.7 | BB6: 762.8 | BC6: 7.91 | BD6: 20 | BE6: 0 | BF6: 12.1 | BG6: 0.15
A7: 43492 | B7: VDSN | C7: FB250 | E7: 132 | F7: 1666 | G7: 0 | H7: 532 | I7: 11 | J7: =P7+O7+N7+M7+L7+K7 -> 0 | K7: 0 | L7: 0 | M7: 0 | N7: 0 | O7: 0 | P7: 0 | Q7: 0 | R7: =G7+S7 -> 0 | S7: 0 | T7: =U7+V7+W7 -> 0 | U7: 0 | V7: 0 | W7: 0 | X7: 0 | Y7: 0 | Z7: =SUM(AA7:AI7) -> 0 | AA7: 0 | AB7: 0 | AC7: 0 | AD7: 0 | AE7: 0 | AF7: 0 | AG7: 0 | AH7: 0 | AI7: 0 | AJ7: 0 | AK7: 0 | AL7: 1 | AM7: 0 | AN7: 0 | AO7: 0 | AP7: =SUM(E7:AO7)-Z7-J7-T7-R7 -> 2342 | AR7: 43492 | AS7: 0.65972222 | AT7: VDSN | AU7: 10 | AV7: YSI 2030 | AW7: 15.76 | AX7: 182.8 | AY7: 0.2043 | AZ7: 0.1 | BA7: 22.7 | BB7: 762.8 | BC7: 7.91 | BD7: 20 | BE7: 0 | BF7: 12.1 | BG7: 0.15
A8: 43492 | B8: VDSN | C8: SW1 | E8: 0 | F8: 1 | G8: 0 | H8: 44 | I8: 1 | J8: =P8+O8+N8+M8+L8+K8 -> 1 | K8: 0 | L8: 0 | M8: 1 | N8: 0 | O8: 0 | P8: 0 | Q8: 0 | R8: =G8+S8 -> 0 | S8: 0 | T8: =U8+V8+W8 -> 0 | U8: 0 | V8: 0 | W8: 0 | X8: 0 | Y8: 0 | Z8: =SUM(AA8:AI8) -> 0 | AA8: 0 | AB8: 0 | AC8: 0 | AD8: 0 | AE8: 0 | AF8: 0 | AG8: 0 | AH8: 0 | AI8: 0 | AJ8: 0 | AK8: 0 | AL8: 0 | AM8: 0 | AN8: 0 | AO8: 0 | AP8: =SUM(E8:AO8)-Z8-J8-T8-R8 -> 47 | AR8: 43492 | AS8: 0.65972222 | AT8: VDSN | AU8: 10 | AV8: YSI 2030 | AW8: 15.76 | AX8: 182.8 | AY8: 0.2043 | AZ8: 0.1 | BA8: 22.7 | BB8: 762.8 | BC8: 7.91 | BD8: 20 | BE8: 0 | BF8: 12.1 | BG8: 0.15
A9: 43493 | B9: VP1 | C9: CORE | E9: 0 | F9: 0 | G9: 0 | H9: 0 | I9: 0 | J9: =P9+O9+N9+M9+L9+K9 -> 0 | K9: 0 | L9: 0 | M9: 0 | N9: 0 | O9: 0 | P9: 0 | Q9: 0 | R9: =G9+S9 -> 0 | S9: 0 | T9: =U9+V9+W9 -> 0 | U9: 0 | V9: 0 | W9: 0 | X9: 0 | Y9: 0 | Z9: =SUM(AA9:AI9) -> 0 | AA9: 0 | AB9: 0 | AC9: 0 | AD9: 0 | AE9: 0 | AF9: 0 | AG9: 0 | AH9: 0 | AI9: 0 | AJ9: 0 | AK9: 0 | AL9: 0 | AM9: 1 | AN9: 0 | AO9: 0 | AP9: =SUM(E9:AO9)-Z9-J9-T9-R9 -> 1 | AR9: 43493 | AS9: 0.63541667 | AT9: CVP1 | AU9: 10 | AV9: YSI 2030 | AW9: 13.9 | AX9: 150 | AY9: 0.095 | AZ9: 0 | BA9: 18.8 | BB9: 760.8 | BC9: 9 | BD9: 74 | BE9: 0 | BF9: 13 | BG9: 0.33
A10: 43493 | B10: VP1 | C10: FB250 | E10: 6 | F10: 293 | G10: 0 | H10: 7 | I10: 2 | J10: =P10+O10+N10+M10+L10+K10 -> 0 | K10: 0 | L10: 0 | M10: 0 | N10: 0 | O10: 0 | P10: 0 | Q10: 0 | R10: =G10+S10 -> 0 | S10: 0 | T10: =U10+V10+W10 -> 0 | U10: 0 | V10: 0 | W10: 0 | X10: 0 | Y10: 0 | Z10: =SUM(AA10:AI10) -> 1 | AA10: 0 | AB10: 0 | AC10: 0 | AD10: 0 | AE10: 0 | AF10: 0 | AG10: 1 | AH10: 0 | AI10: 0 | AJ10: 0 | AK10: 3 | AL10: 0 | AM10: 0 | AN10: 0 | AO10: 0 | AP10: =SUM(E10:AO10)-Z10-J10-T10-R10 -> 312 | AR10: 43493 | AS10: 0.63541667 | AT10: CVP1 | AU10: 10 | AV10: YSI 2030 | AW10: 13.9 | AX10: 150 | AY10: 0.095 | AZ10: 0 | BA10: 18.8 | BB10: 760.8 | BC10: 9 | BD10: 74 | BE10: 0 | BF10: 13 | BG10: 0.33
A11: 43493 | B11: VP1 | C11: SW1 | E11: 116 | F11: 23 | G11: 0 | H11: 6 | I11: 3 | J11: =P11+O11+N11+M11+L11+K11 -> 0 | K11: 0 | L11: 0 | M11: 0 | N11: 0 | O11: 0 | P11: 0 | Q11: 0 | R11: =G11+S11 -> 0 | S11: 0 | T11: =U11+V11+W11 -> 0 | U11: 0 | V11: 0 | W11: 0 | X11: 0 | Y11: 0 | Z11: =SUM(AA11:AI11) -> 0 | AA11: 0 | AB11: 0 | AC11: 0 | AD11: 0 | AE11: 0 | AF11: 0 | AG11: 0 | AH11: 0 | AI11: 0 | AJ11: 0 | AK11: 1 | AL11: 0 | AM11: 11 | AN11: 0 | AO11: 0 | AP11: =SUM(E11:AO11)-Z11-J11-T11-R11 -> 160 | AR11: 43493 | AS11: 0.63541667 | AT11: CVP1 | AU11: 10 | AV11: YSI 2030 | AW11: 13.9 | AX11: 150 | AY11: 0.095 | AZ11: 0 | BA11: 18.8 | BB11: 760.8 | BC11: 9 | BD11: 74 | BE11: 0 | BF11: 13 | BG11: 0.33
A12: 43493 | B12: CUL1 | C12: FB250 | E12: 86 | F12: 141 | G12: 68 | H12: 0 | I12: 0 | J12: =P12+O12+N12+M12+L12+K12 -> 7 | K12: 0 | L12: 0 | M12: 6 | N12: 0 | O12: 0 | P12: 1 | Q12: 0 | R12: =G12+S12 -> 68 | S12: 0 | T12: =U12+V12+W12 -> 0 | U12: 0 | V12: 0 | W12: 0 | X12: 0 | Y12: 0 | Z12: =SUM(AA12:AI12) -> 0 | AA12: 0 | AB12: 0 | AC12: 0 | AD12: 0 | AE12: 0 | AF12: 0 | AG12: 0 | AH12: 0 | AI12: 0 | AJ12: 0 | AK12: 4 | AL12: 0 | AM12: 2 | AN12: 0 | AO12: 0 | AP12: =SUM(E12:AO12)-Z12-J12-T12-R12 -> 308 | AR12: 43493 | AS12: 0.54861111 | AT12: CUL 1 | AU12: 10 | AV12: YSI 2030 | AW12: 0.1 | AX12: 1 | AY12: 22.6 | AZ12: 14 | BA12: 13 | BB12: 761.9 | BC12: 7.38 | BD12: 0 | BE12: 0 | BF12: 1 | BG12: 0.3
A13: 43495 | B13: VNVP4 | C13: CORE | E13: 1 | F13: 0 | G13: 0 | H13: 9 | I13: 0 | J13: =P13+O13+N13+M13+L13+K13 -> 7 | K13: 0 | L13: 7 | M13: 0 | N13: 0 | O13: 0 | P13: 0 | Q13: 0 | R13: =G13+S13 -> 0 | S13: 0 | T13: =U13+V13+W13 -> 0 | U13: 0 | V13: 0 | W13: 0 | X13: 0 | Y13: 0 | Z13: =SUM(AA13:AI13) -> 0 | AA13: 0 | AB13: 0 | AC13: 0 | AD13: 0 | AE13: 0 | AF13: 0 | AG13: 0 | AH13: 0 | AI13: 0 | AJ13: 0 | AK13: 0 | AL13: 0 | AM13: 0 | AN13: 0 | AO13: 0 | AP13: =SUM(E13:AO13)-Z13-J13-T13-R13 -> 17 | AR13: 43495 | AS13: 0.47916667 | AT13: NVP4 | AU13: 10 | AV13: YSI 2030 | AW13: 8.181 | AX13: 86.5 | AY13: 0.32 | AZ13: 0.2 | BA13: 18 | BB13: 760 | BC13: 8.51 | BD13: 3 | BE13: 0 | BF13: 17 | BG13: 0.3
A14: 43495 | B14: VNVP4 | C14: FB250 | E14: 2 | F14: 7 | G14: 0 | H14: 136 | I14: 0 | J14: =P14+O14+N14+M14+L14+K14 -> 7 | K14: 0 | L14: 0 | M14: 7 | N14: 0 | O14: 0 | P14: 0 | Q14: 0 | R14: =G14+S14 -> 0 | S14: 0 | T14: =U14+V14+W14 -> 0 | U14: 0 | V14: 0 | W14: 0 | X14: 0 | Y14: 0 | Z14: =SUM(AA14:AI14) -> 0 | AA14: 0 | AB14: 0 | AC14: 0 | AD14: 0 | AE14: 0 | AF14: 0 | AG14: 0 | AH14: 0 | AI14: 0 | AJ14: 0 | AK14: 0 | AL14: 0 | AM14: 0 | AN14: 0 | AO14: 0 | AP14: =SUM(E14:AO14)-Z14-J14-T14-R14 -> 152 | AR14: 43495 | AS14: 0.47916667 | AT14: NVP4 | AU14: 10 | AV14: YSI 2030 | AW14: 8.181 | AX14: 86.5 | AY14: 0.32 | AZ14: 0.2 | BA14: 18 | BB14: 760 | BC14: 8.51 | BD14: 3 | BE14: 0 | BF14: 17 | BG14: 0.3
A15: 43495 | B15: VNVP4 | C15: SW1 | E15: 133 | F15: 0 | G15: 0 | H15: 1881 | I15: 0 | J15: =P15+O15+N15+M15+L15+K15 -> 12 | K15: 0 | L15: 12 | M15: 0 | N15: 0 | O15: 0 | P15: 0 | Q15: 0 | R15: =G15+S15 -> 0 | S15: 0 | T15: =U15+V15+W15 -> 0 | U15: 0 | V15: 0 | W15: 0 | X15: 0 | Y15: 0 | Z15: =SUM(AA15:AI15) -> 0 | AA15: 0 | AB15: 0 | AC15: 0 | AD15: 0 | AE15: 0 | AF15: 0 | AG15: 0 | AH15: 0 | AI15: 0 | AJ15: 0 | AK15: 0 | AL15: 0 | AM15: 0 | AN15: 0 | AO15: 0 | AP15: =SUM(E15:AO15)-Z15-J15-T15-R15 -> 2026 | AR15: 43495 | AS15: 0.47916667 | AT15: NVP4 | AU15: 10 | AV15: YSI 2030 | AW15: 8.181 | AX15: 86.5 | AY15: 0.32 | AZ15: 0.2 | BA15: 18 | BB15: 760 | BC15: 8.51 | BD15: 3 | BE15: 0 | BF15: 17 | BG15: 0.3
A16: 43502 | B16: DSP | C16: FB250 | E16: 324 | F16: 15 | G16: 0 | H16: 0 | I16: 0 | J16: =P16+O16+N16+M16+L16+K16 -> 10 | K16: 0 | L16: 7 | M16: 0 | N16: 3 | O16: 0 | P16: 0 | Q16: 0 | R16: =G16+S16 -> 0 | S16: 0 | T16: =U16+V16+W16 -> 0 | U16: 0 | V16: 0 | W16: 0 | X16: 0 | Y16: 0 | Z16: =SUM(AA16:AI16) -> 0 | AA16: 0 | AB16: 0 | AC16: 0 | AD16: 0 | AE16: 0 | AF16: 0 | AG16: 0 | AH16: 0 | AI16: 0 | AJ16: 0 | AK16: 0 | AL16: 0 | AM16: 3 | AN16: 0 | AO16: 0 | AP16: =SUM(E16:AO16)-Z16-J16-T16-R16 -> 352 | AR16: 6-Feb-19 | AS16: 11:30 | AT16: DSP | AU16: 10 | AV16: YSI 2030 | AW16: 7.46 | AX16: 69.1 | AY16: 0 | AZ16: 0 | BA16: 12 | BB16: 766 | BC16: 7.2 | BD16: 0 | BE16: 0 | BF16: 2 | BG16: 1
A17: 43502 | B17: DSP | C17: SW1 | E17: 6 | F17: 1 | G17: 0 | H17: 2 | I17: 0 | J17: =P17+O17+N17+M17+L17+K17 -> 27 | K17: 0 | L17: 0 | M17: 4 | N17: 23 | O17: 0 | P17: 0 | Q17: 0 | R17: =G17+S17 -> 0 | S17: 0 | T17: =U17+V17+W17 -> 2 | U17: 0 | V17: 2 | W17: 0 | X17: 0 | Y17: 0 | Z17: =SUM(AA17:AI17) -> 0 | AA17: 0 | AB17: 0 | AC17: 0 | AD17: 0 | AE17: 0 | AF17: 0 | AG17: 0 | AH17: 0 | AI17: 0 | AJ17: 0 | AK17: 0 | AL17: 0 | AM17: 0 | AN17: 0 | AO17: 0 | AP17: =SUM(E17:AO17)-Z17-J17-T17-R17 -> 38 | AR17: 6-Feb-19 | AS17: 11:30 | AT17: DSP | AU17: 10 | AV17: YSI 2030 | AW17: 7.46 | AX17: 69.1 | AY17: 0 | AZ17: 0 | BA17: 12 | BB17: 766 | BC17: 7.2 | BD17: 0 | BE17: 0 | BF17: 2 | BG17: 1
A18: 43502 | B18: NEC | C18: FB250 | E18: 30 | F18: 34 | G18: 2 | H18: 26 | I18: 0 | J18: =P18+O18+N18+M18+L18+K18 -> 0 | K18: 0 | L18: 0 | M18: 0 | N18: 0 | O18: 0 | P18: 0 | Q18: 0 | R18: =G18+S18 -> 2 | S18: 0 | T18: =U18+V18+W18 -> 0 | U18: 0 | V18: 0 | W18: 0 | X18: 0 | Y18: 0 | Z18: =SUM(AA18:AI18) -> 0 | AA18: 0 | AB18: 0 | AC18: 0 | AD18: 0 | AE18: 0 | AF18: 0 | AG18: 0 | AH18: 0 | AI18: 0 | AJ18: 0 | AK18: 0 | AL18: 0 | AM18: 9 | AN18: 0 | AO18: 0 | AP18: =SUM(E18:AO18)-Z18-J18-T18-R18 -> 101 | AR18: 6-Feb-19 | AS18: 13:35 | AT18: NEC | AU18: 10 | AV18: YSI 2030 | AW18: 12.08 | AX18: 118.7 | AY18: 1.51 | AZ18: 0.8 | BA18: 14.2 | BB18: 765.4 | BC18: 7.49 | BD18: - | BE18: - | BF18: - | BG18: -
A19: 43502 | B19: NMC | C19: FB250 | E19: 10 | F19: 290 | G19: 4 | H19: 5 | I19: 0 | J19: =P19+O19+N19+M19+L19+K19 -> 0 | K19: 0 | L19: 0 | M19: 0 | N19: 0 | O19: 0 | P19: 0 | Q19: 0 | R19: =G19+S19 -> 4 | S19: 0 | T19: =U19+V19+W19 -> 0 | U19: 0 | V19: 0 | W19: 0 | X19: 0 | Y19: 0 | Z19: =SUM(AA19:AI19) -> 0 | AA19: 0 | AB19: 0 | AC19: 0 | AD19: 0 | AE19: 0 | AF19: 0 | AG19: 0 | AH19: 0 | AI19: 0 | AJ19: 0 | AK19: 0 | AL19: 0 | AM19: 0 | AN19: 0 | AO19: 0 | AP19: =SUM(E19:AO19)-Z19-J19-T19-R19 -> 309 | AR19: 6-Feb-19 | AS19: 14:00 | AT19: NMC | AU19: 10 | AV19: YSI 2030 | AW19: 11.67 | AX19: 112.6 | AY19: 0 | AZ19: 0 | BA19: 13.3 | BB19: 765.3 | BC19: 7.32 | BD19: - | BE19: - | BF19: - | BG19: -
A20: 43502 | B20: NVBR | C20: FB250 | E20: 2 | F20: 0 | G20: 0 | H20: 6 | I20: 0 | J20: =P20+O20+N20+M20+L20+K20 -> 0 | K20: 0 | L20: 0 | M20: 0 | N20: 0 | O20: 0 | P20: 0 | Q20: 1 | R20: =G20+S20 -> 0 | S20: 0 | T20: =U20+V20+W20 -> 0 | U20: 0 | V20: 0 | W20: 0 | X20: 0 | Y20: 0 | Z20: =SUM(AA20:AI20) -> 0 | AA20: 0 | AB20: 0 | AC20: 0 | AD20: 0 | AE20: 0 | AF20: 0 | AG20: 0 | AH20: 0 | AI20: 0 | AJ20: 0 | AK20: 0 | AL20: 0 | AM20: 0 | AN20: 0 | AO20: 0 | AP20: =SUM(E20:AO20)-Z20-J20-T20-R20 -> 9 | AR20: 6-Feb-19 | AS20: 13:10 | AT20: NVBR | AU20: 10 | AV20: YSI 2030 | AW20: 13.05 | AX20: 130.4 | AY20: 0 | AZ20: 0 | BA20: 14.4 | BB20: 765.8 | BC20: 7.62 | BD20: - | BE20: - | BF20: - | BG20: -
A21: 43502 | B21: VBR1 | C21: FB250 | E21: 2 | F21: 4 | G21: 0 | H21: 0 | I21: 0 | J21: =P21+O21+N21+M21+L21+K21 -> 0 | K21: 0 | L21: 0 | M21: 0 | N21: 0 | O21: 0 | P21: 0 | Q21: 0 | R21: =G21+S21 -> 0 | S21: 0 | T21: =U21+V21+W21 -> 0 | U21: 0 | V21: 0 | W21: 0 | X21: 0 | Y21: 0 | Z21: =SUM(AA21:AI21) -> 0 | AA21: 0 | AB21: 0 | AC21: 0 | AD21: 0 | AE21: 0 | AF21: 0 | AG21: 0 | AH21: 0 | AI21: 0 | AJ21: 0 | AK21: 0 | AL21: 0 | AM21: 0 | AN21: 0 | AO21: 0 | AP21: =SUM(E21:AO21)-Z21-J21-T21-R21 -> 6 | AR21: 6-Feb-19 | AS21: 13:00 | AT21: VBR1 | AU21: 10 | AV21: YSI 2030 | AW21: 11.24 | AX21: 105 | AY21: 0.0975 | AZ21: 0 | BA21: 12.5 | BB21: 765.2 | BC21: 7.27 | BD21: - | BE21: - | BF21: - | BG21: -
A22: 43503 | B22: VNVP2 | C22: CORE | E22: 7 | F22: 0 | G22: 0 | H22: 40 | I22: 0 | J22: =P22+O22+N22+M22+L22+K22 -> 6 | K22: 0 | L22: 6 | M22: 0 | N22: 0 | O22: 0 | P22: 0 | Q22: 0 | R22: =G22+S22 -> 0 | S22: 0 | T22: =U22+V22+W22 -> 0 | U22: 0 | V22: 0 | W22: 0 | X22: 0 | Y22: 0 | Z22: =SUM(AA22:AI22) -> 1 | AA22: 0 | AB22: 1 | AC22: 0 | AD22: 0 | AE22: 0 | AF22: 0 | AG22: 0 | AH22: 0 | AI22: 0 | AJ22: 0 | AK22: 0 | AL22: 0 | AM22: 0 | AN22: 0 | AO22: 0 | AP22: =SUM(E22:AO22)-Z22-J22-T22-R22 -> 54 | AR22: 7-Feb-19 | AS22: 11:50 | AT22: NVP2 | AU22: 10 | AV22: YSI 2030 | AW22: 10.3 | AX22: 101 | AY22: 0.39 | AZ22: 0.2 | BA22: 15.3 | BB22: 768.7 | BC22: 7.6 | BD22: 1 | BE22: - | BF22: 32 | BG22: 0.5
A23: 43503 | B23: VNVP2 | C23: FB250 | E23: 229 | F23: 13 | G23: 0 | H23: 2834 | I23: 1 | J23: =P23+O23+N23+M23+L23+K23 -> 22 | K23: 0 | L23: 22 | M23: 0 | N23: 0 | O23: 0 | P23: 0 | Q23: 0 | R23: =G23+S23 -> 0 | S23: 0 | T23: =U23+V23+W23 -> 0 | U23: 0 | V23: 0 | W23: 0 | X23: 0 | Y23: 0 | Z23: =SUM(AA23:AI23) -> 0 | AA23: 0 | AB23: 0 | AC23: 0 | AD23: 0 | AE23: 0 | AF23: 0 | AG23: 0 | AH23: 0 | AI23: 0 | AJ23: 0 | AK23: 0 | AL23: 0 | AM23: 1 | AN23: 0 | AO23: 0 | AP23: =SUM(E23:AO23)-Z23-J23-T23-R23 -> 3100 | AR23: 7-Feb-19 | AS23: 11:50 | AT23: NVP2 | AU23: 10 | AV23: YSI 2030 | AW23: 10.3 | AX23: 101 | AY23: 0.39 | AZ23: 0.2 | BA23: 15.3 | BB23: 768.7 | BC23: 7.6 | BD23: 1 | BE23: - | BF23: 32 | BG23: 0.5
A24: 43503 | B24: VNVP2 | C24: SW1 | E24: 190 | F24: 0 | G24: 0 | H24: 760 | I24: 0 | J24: =P24+O24+N24+M24+L24+K24 -> 0 | K24: 0 | L24: 0 | M24: 0 | N24: 0 | O24: 0 | P24: 0 | Q24: 0 | R24: =G24+S24 -> 0 | S24: 0 | T24: =U24+V24+W24 -> 0 | U24: 0 | V24: 0 | W24: 0 | X24: 0 | Y24: 0 | Z24: =SUM(AA24:AI24) -> 0 | AA24: 0 | AB24: 0 | AC24: 0 | AD24: 0 | AE24: 0 | AF24: 0 | AG24: 0 | AH24: 0 | AI24: 0 | AJ24: 0 | AK24: 0 | AL24: 0 | AM24: 0 | AN24: 0 | AO24: 0 | AP24: =SUM(E24:AO24)-Z24-J24-T24-R24 -> 950 | AR24: 7-Feb-19 | AS24: 11:50 | AT24: NVP2 | AU24: 10 | AV24: YSI 2030 | AW24: 10.3 | AX24: 101 | AY24: 0.39 | AZ24: 0.2 | BA24: 15.3 | BB24: 768.7 | BC24: 7.6 | BD24: 1 | BE24: - | BF24: 32 | BG24: 0.5
A25: 43504 | B25: VNVP10 | C25: CORE | E25: 1 | F25: 1 | G25: 0 | H25: 3 | I25: 1 | J25: =P25+O25+N25+M25+L25+K25 -> 5 | K25: 0 | L25: 5 | M25: 0 | N25: 0 | O25: 0 | P25: 0 | Q25: 0 | R25: =G25+S25 -> 0 | S25: 0 | T25: =U25+V25+W25 -> 0 | U25: 0 | V25: 0 | W25: 0 | X25: 0 | Y25: 0 | Z25: =SUM(AA25:AI25) -> 0 | AA25: 0 | AC25: 0 | AD25: 0 | AE25: 0 | AF25: 0 | AG25: 0 | AH25: 0 | AI25: 0 | AJ25: 0 | AK25: 0 | AL25: 0 | AM25: 0 | AN25: 0 | AP25: =SUM(E25:AO25)-Z25-J25-T25-R25 -> 11 | AR25: 8-Feb-19 | AS25: 14:10 | AT25: NVP10 | AU25: 10 | AV25: YSI 2030 | AW25: 8.79 | AX25: 95.8 | AY25: 0.0755 | AZ25: 0 | BA25: 19.5 | BB25: 762.6 | BC25: 7.5 | BD25: 18 | BE25: 0 | BF25: 13 | BG25: 0.28
A26: 43504 | B26: VNVP10 | C26: FB250 | E26: 75 | F26: 189 | G26: 0 | H26: 740 | I26: 0 | J26: =P26+O26+N26+M26+L26+K26 -> 0 | K26: 0 | L26: 0 | M26: 0 | N26: 0 | O26: 0 | P26: 0 | Q26: 0 | R26: =G26+S26 -> 0 | S26: 0 | T26: =U26+V26+W26 -> 0 | U26: 0 | V26: 0 | W26: 0 | X26: 0 | Y26: 0 | Z26: =SUM(AA26:AI26) -> 0 | AA26: 0 | AB26: 0 | AC26: 0 | AD26: 0 | AE26: 0 | AF26: 0 | AG26: 0 | AH26: 0 | AI26: 0 | AJ26: 0 | AK26: 0 | AL26: 0 | AM26: 0 | AN26: 0 | AO26: 0 | AP26: =SUM(E26:AO26)-Z26-J26-T26-R26 -> 1004 | AR26: 8-Feb-19 | AS26: 14:10 | AT26: NVP10 | AU26: 10 | AV26: YSI 2030 | AW26: 8.79 | AX26: 95.8 | AY26: 0.0755 | AZ26: 0 | BA26: 19.5 | BB26: 762.6 | BC26: 7.5 | BD26: 18 | BE26: 0 | BF26: 13 | BG26: 0.28
A27: 43504 | B27: VNVP10 | C27: SW1 | E27: 682 | F27: 2 | G27: 0 | H27: 288 | I27: 0 | J27: =P27+O27+N27+M27+L27+K27 -> 1 | K27: 1 | L27: 0 | M27: 0 | N27: 0 | O27: 0 | P27: 0 | Q27: 0 | R27: =G27+S27 -> 0 | S27: 0 | T27: =U27+V27+W27 -> 0 | U27: 0 | V27: 0 | W27: 0 | X27: 0 | Y27: 0 | Z27: =SUM(AA27:AI27) -> 3 | AA27: 0 | AB27: 0 | AC27: 1 | AD27: 0 | AE27: 1 | AF27: 1 | AG27: 0 | AH27: 0 | AI27: 0 | AJ27: 0 | AK27: 0 | AL27: 0 | AM27: 0 | AN27: 0 | AO27: 0 | AP27: =SUM(E27:AO27)-Z27-J27-T27-R27 -> 976 | AR27: 8-Feb-19 | AS27: 14:10 | AT27: NVP10 | AU27: 10 | AV27: YSI 2030 | AW27: 8.79 | AX27: 95.8 | AY27: 0.0755 | AZ27: 0 | BA27: 19.5 | BB27: 762.6 | BC27: 7.5 | BD27: 18 | BE27: 0 | BF27: 13 | BG27: 0.28
A28: 43507 | B28: VCC7 | C28: CORE | E28: 0 | F28: 0 | G28: 0 | H28: 4 | I28: 2 | J28: =P28+O28+N28+M28+L28+K28 -> 0 | K28: 0 | L28: 0 | M28: 0 | N28: 0 | O28: 0 | P28: 0 | Q28: 0 | R28: =G28+S28 -> 0 | S28: 0 | T28: =U28+V28+W28 -> 2 | U28: 0 | V28: 2 | W28: 0 | X28: 0 | Y28: 0 | Z28: =SUM(AA28:AI28) -> 0 | AA28: 0 | AB28: 0 | AC28: 0 | AD28: 0 | AE28: 0 | AF28: 0 | AG28: 0 | AH28: 0 | AI28: 0 | AJ28: 0 | AK28: 0 | AL28: 0 | AM28: 0 | AN28: 0 | AO28: 0 | AP28: =SUM(E28:AO28)-Z28-J28-T28-R28 -> 8 | AR28: 11-Feb-19 | AS28: 15:35 | AT28: VM7 | AU28: 10 | AV28: YSI 2030 | AW28: 15.87 | AX28: 168.3 | AY28: 0.158 | AZ28: 0.1 | BA28: 18.2 | BB28: 764.7 | BC28: 8.8 | BD28: 7 | BE28: - | BF28: 8 | BG28: 0.27
A29: 43507 | B29: VCC7 | C29: FB250 | E29: 19 | F29: 52 | G29: 0 | H29: 195 | I29: 0 | J29: =P29+O29+N29+M29+L29+K29 -> 0 | K29: 0 | L29: 0 | M29: 0 | N29: 0 | O29: 0 | P29: 0 | Q29: 0 | R29: =G29+S29 -> 0 | S29: 0 | T29: =U29+V29+W29 -> 0 | U29: 0 | V29: 0 | W29: 0 | X29: 0 | Y29: 0 | Z29: =SUM(AA29:AI29) -> 0 | AA29: 0 | AB29: 0 | AC29: 0 | AD29: 0 | AE29: 0 | AF29: 0 | AG29: 0 | AH29: 0 | AI29: 0 | AJ29: 0 | AK29: 0 | AL29: 0 | AM29: 0 | AN29: 0 | AO29: 0 | AP29: =SUM(E29:AO29)-Z29-J29-T29-R29 -> 266 | AR29: 11-Feb-19 | AS29: 15:35 | AT29: VM7 | AU29: 10 | AV29: YSI 2030 | AW29: 15.87 | AX29: 168.3 | AY29: 0.158 | AZ29: 0.1 | BA29: 18.2 | BB29: 764.7 | BC29: 8.8 | BD29: 7 | BE29: - | BF29: 8 | BG29: 0.27
A30: 43507 | B30: VCC7 | C30: SW1 | E30: 710 | F30: 485 | G30: 1 | H30: 0 | I30: 0 | J30: =P30+O30+N30+M30+L30+K30 -> 2 | K30: 0 | L30: 2 | M30: 0 | N30: 0 | O30: 0 | P30: 0 | Q30: 0 | R30: =G30+S30 -> 1 | S30: 0 | T30: =U30+V30+W30 -> 0 | U30: 0 | V30: 0 | W30: 0 | X30: 0 | Y30: 0 | Z30: =SUM(AA30:AI30) -> 4 | AA30: 0 | AB30: 0 | AC30: 0 | AD30: 4 | AE30: 0 | AF30: 0 | AG30: 0 | AH30: 0 | AI30: 0 | AJ30: 0 | AK30: 4 | AL30: 0 | AM30: 0 | AN30: 0 | AO30: 0 | AP30: =SUM(E30:AO30)-Z30-J30-T30-R30 -> 1206 | AR30: 11-Feb-19 | AS30: 15:35 | AT30: VM7 | AU30: 10 | AV30: YSI 2030 | AW30: 15.87 | AX30: 168.3 | AY30: 0.158 | AZ30: 0.1 | BA30: 18.2 | BB30: 764.7 | BC30: 8.8 | BD30: 7 | BE30: - | BF30: 8 | BG30: 0.27
A31: 43507 | B31: VM7 | C31: CORE | E31: 4 | F31: 0 | G31: 0 | H31: 16 | I31: 0 | J31: =P31+O31+N31+M31+L31+K31 -> 0 | K31: 0 | L31: 0 | M31: 0 | N31: 0 | O31: 0 | P31: 0 | Q31: 0 | R31: =G31+S31 -> 0 | S31: 0 | T31: =U31+V31+W31 -> 0 | U31: 0 | V31: 0 | W31: 0 | X31: 0 | Y31: 0 | Z31: =SUM(AA31:AI31) -> 0 | AA31: 0 | AB31: 0 | AC31: 0 | AD31: 0 | AE31: 0 | AF31: 0 | AG31: 0 | AH31: 0 | AI31: 0 | AJ31: 0 | AK31: 0 | AL31: 0 | AM31: 3 | AN31: 0 | AO31: 0 | AP31: =SUM(E31:AO31)-Z31-J31-T31-R31 -> 23 | AR31: 11-Feb-19 | AS31: 15:35 | AT31: VM7 | AU31: 10 | AV31: YSI 2030 | AW31: 15.87 | AX31: 168.3 | AY31: 0.158 | AZ31: 0.1 | BA31: 18.2 | BB31: 764.7 | BC31: 8.8 | BD31: 7 | BE31: - | BF31: 8 | BG31: 0.27
A32: 43507 | B32: VM7 | C32: FB250 | E32: 60 | F32: 95 | G32: 0 | H32: 708 | I32: 1 | J32: =P32+O32+N32+M32+L32+K32 -> 0 | K32: 0 | L32: 0 | M32: 0 | N32: 0 | O32: 0 | P32: 0 | Q32: 0 | R32: =G32+S32 -> 0 | S32: 0 | T32: =U32+V32+W32 -> 0 | U32: 0 | V32: 0 | W32: 0 | X32: 0 | Y32: 0 | Z32: =SUM(AA32:AI32) -> 0 | AA32: 0 | AB32: 0 | AC32: 0 | AD32: 0 | AE32: 0 | AF32: 0 | AG32: 0 | AH32: 0 | AI32: 0 | AJ32: 0 | AK32: 0 | AL32: 0 | AM32: 0 | AN32: 0 | AO32: 0 | AP32: =SUM(E32:AO32)-Z32-J32-T32-R32 -> 864 | AR32: 11-Feb-19 | AS32: 15:35 | AT32: VM7 | AU32: 10 | AV32: YSI 2030 | AW32: 15.87 | AX32: 168.3 | AY32: 0.158 | AZ32: 0.1 | BA32: 18.2 | BB32: 764.7 | BC32: 8.8 | BD32: 7 | BE32: - | BF32: 8 | BG32: 0.27
A33: 43507 | B33: VM7 | C33: SW1 | E33: 664 | F33: 5 | G33: 0 | H33: 350 | I33: 0 | J33: =P33+O33+N33+M33+L33+K33 -> 8 | K33: 0 | L33: 6 | M33: 0 | N33: 0 | O33: 2 | P33: 0 | Q33: 1 | R33: =G33+S33 -> 0 | S33: 0 | T33: =U33+V33+W33 -> 0 | U33: 0 | V33: 0 | W33: 0 | X33: 0 | Y33: 0 | Z33: =SUM(AA33:AI33) -> 1 | AA33: 0 | AB33: 1 | AC33: 0 | AD33: 0 | AE33: 0 | AF33: 0 | AG33: 0 | AH33: 0 | AI33: 0 | AJ33: 0 | AK33: 5 | AL33: 0 | AM33: 0 | AN33: 0 | AO33: 0 | AP33: =SUM(E33:AO33)-Z33-J33-T33-R33 -> 1034 | AR33: 11-Feb-19 | AS33: 15:35 | AT33: VM7 | AU33: 10 | AV33: YSI 2030 | AW33: 15.87 | AX33: 168.3 | AY33: 0.158 | AZ33: 0.1 | BA33: 18.2 | BB33: 764.7 | BC33: 8.8 | BD33: 7 | BE33: - | BF33: 8 | BG33: 0.27
A34: 43507 | B34: VOW1 | C34: CORE | E34: 0 | F34: 0 | G34: 0 | H34: 1 | I34: 0 | J34: =P34+O34+N34+M34+L34+K34 -> 0 | K34: 0 | L34: 0 | M34: 0 | N34: 0 | O34: 0 | P34: 0 | Q34: 0 | R34: =G34+S34 -> 0 | S34: 0 | T34: =U34+V34+W34 -> 0 | U34: 0 | V34: 0 | W34: 0 | X34: 0 | Y34: 0 | Z34: =SUM(AA34:AI34) -> 0 | AA34: 0 | AB34: 0 | AC34: 0 | AD34: 0 | AE34: 0 | AF34: 0 | AG34: 0 | AH34: 0 | AI34: 0 | AJ34: 0 | AK34: 0 | AL34: 0 | AM34: 0 | AN34: 0 | AO34: 0 | AP34: =SUM(E34:AO34)-Z34-J34-T34-R34 -> 1 | AR34: 11-Feb19 | AS34: 10:50 | AT34: VOW1 | AU34: 10 | AV34: YSI 2030 | AW34: 5.74 | AX34: 50.1 | AY34: 0.03 | AZ34: 0 | BA34: 9.3 | BB34: 766 | BC34: 6.9 | BD34: 7 | BE34: 0 | BF34: 30 | BG34: 0.42
A35: 43507 | B35: VOW1 | C35: FB250 | E35: 923 | F35: 89 | G35: 0 | H35: 768 | I35: 0 | J35: =P35+O35+N35+M35+L35+K35 -> 0 | K35: 0 | L35: 0 | M35: 0 | N35: 0 | O35: 0 | P35: 0 | Q35: 0 | R35: =G35+S35 -> 0 | S35: 0 | T35: =U35+V35+W35 -> 0 | U35: 0 | V35: 0 | W35: 0 | X35: 0 | Y35: 0 | Z35: =SUM(AA35:AI35) -> 0 | AA35: 0 | AB35: 0 | AC35: 0 | AD35: 0 | AE35: 0 | AF35: 0 | AG35: 0 | AH35: 0 | AI35: 0 | AJ35: 0 | AK35: 0 | AL35: 0 | AM35: 1 | AN35: 0 | AO35: 0 | AP35: =SUM(E35:AO35)-Z35-J35-T35-R35 -> 1781 | AR35: 11-Feb19 | AS35: 10:50 | AT35: VOW1 | AU35: 10 | AV35: YSI 2030 | AW35: 5.74 | AX35: 50.1 | AY35: 0.03 | AZ35: 0 | BA35: 9.3 | BB35: 766 | BC35: 6.9 | BD35: 7 | BE35: 0 | BF35: 30 | BG35: 0.42
A36: 43507 | B36: VOW1 | C36: SW1 | E36: 1209 | F36: 21 | G36: 0 | H36: 1418 | I36: 0 | J36: =P36+O36+N36+M36+L36+K36 -> 1 | K36: 0 | L36: 1 | M36: 0 | N36: 0 | O36: 0 | P36: 0 | Q36: 0 | R36: =G36+S36 -> 0 | S36: 0 | T36: =U36+V36+W36 -> 0 | U36: 0 | V36: 0 | W36: 0 | X36: 0 | Y36: 0 | Z36: =SUM(AA36:AI36) -> 0 | AA36: 0 | AB36: 0 | AC36: 0 | AD36: 0 | AE36: 0 | AF36: 0 | AG36: 0 | AH36: 0 | AI36: 0 | AJ36: 0 | AK36: 0 | AL36: 0 | AM36: 0 | AN36: 0 | AO36: 0 | AP36: =SUM(E36:AO36)-Z36-J36-T36-R36 -> 2649 | AR36: 11-Feb19 | AS36: 10:50 | AT36: VOW1 | AU36: 10 | AV36: YSI 2030 | AW36: 5.74 | AX36: 50.1 | AY36: 0.03 | AZ36: 0 | BA36: 9.3 | BB36: 766 | BC36: 6.9 | BD36: 7 | BE36: 0 | BF36: 30 | BG36: 0.42
A37: 43507 | B37: VM3 | C37: FB250 | E37: 174 | F37: 90 | G37: 0 | H37: 343 | I37: 0 | J37: =P37+O37+N37+M37+L37+K37 -> 0 | K37: 0 | L37: 0 | M37: 0 | N37: 0 | O37: 0 | P37: 0 | Q37: 0 | R37: =G37+S37 -> 0 | S37: 0 | T37: =U37+V37+W37 -> 0 | U37: 0 | V37: 0 | W37: 0 | X37: 0 | Y37: 0 | Z37: =SUM(AA37:AI37) -> 0 | AA37: 0 | AB37: 0 | AC37: 0 | AD37: 0 | AE37: 0 | AF37: 0 | AG37: 0 | AH37: 0 | AI37: 0 | AJ37: 0 | AK37: 0 | AL37: 0 | AM37: 0 | AN37: 0 | AO37: 0 | AP37: =SUM(E37:AO37)-Z37-J37-T37-R37 -> 607 | AR37: 11-Feb-19 | AS37: 14:30 | AT37: VM3 | AU37: 10 | AV37: YSI 2030 | AW37: 9.4 | AX37: 99.5 | AY37: 0 | AZ37: 0 | BA37: 18.1 | BB37: 765 | BC37: 6.8 | BD37: 2 | BE37: - | BF37: 17 | BG37: 0.42 | BI37: e
A38: 43507 | B38: VM3 | C38: SW1 | E38: 1330 | F38: 0 | G38: 0 | H38: 932 | I38: 1 | J38: =P38+O38+N38+M38+L38+K38 -> 0 | K38: 0 | L38: 0 | M38: 0 | N38: 0 | O38: 0 | P38: 0 | Q38: 0 | R38: =G38+S38 -> 0 | S38: 0 | T38: =U38+V38+W38 -> 0 | U38: 0 | V38: 0 | W38: 0 | X38: 0 | Y38: 0 | Z38: =SUM(AA38:AI38) -> 2 | AA38: 0 | AB38: 0 | AC38: 0 | AD38: 0 | AE38: 0 | AF38: 0 | AG38: 0 | AH38: 2 | AI38: 0 | AJ38: 0 | AK38: 0 | AL38: 0 | AM38: 0 | AN38: 0 | AO38: 0 | AP38: =SUM(E38:AO38)-Z38-J38-T38-R38 -> 2265 | AR38: 11-Feb-19 | AS38: 14:30 | AT38: VM3 | AU38: 10 | AV38: YSI 2030 | AW38: 9.4 | AX38: 99.5 | AY38: 0 | AZ38: 0 | BA38: 18.1 | BB38: 765 | BC38: 6.8 | BD38: 2 | BE38: - | BF38: 17 | BG38: 0.42
A39: 43514 | B39: NDC | C39: FB250 | E39: 59 | F39: 25 | G39: 0 | H39: 241 | I39: 0 | J39: =P39+O39+N39+M39+L39+K39 -> 1 | K39: 0 | L39: 0 | M39: 1 | N39: 0 | O39: 0 | P39: 0 | Q39: 0 | R39: =G39+S39 -> 0 | S39: 0 | T39: =U39+V39+W39 -> 0 | U39: 0 | V39: 0 | W39: 0 | X39: 0 | Y39: 0 | Z39: =SUM(AA39:AI39) -> 0 | AA39: 0 | AB39: 0 | AC39: 0 | AD39: 0 | AE39: 0 | AF39: 0 | AG39: 0 | AH39: 0 | AI39: 0 | AJ39: 0 | AK39: 0 | AL39: 0 | AM39: 3 | AN39: 0 | AO39: 0 | AP39: =SUM(E39:AO39)-Z39-J39-T39-R39 -> 329 | AR39: 18-Feb-19 | AS39: 11:10 | AT39: NDC | AU39: 10 | AV39: YSI 2030 | AW39: 2.71 | AX39: 23.8 | AY39: 0.608 | AZ39: 0.3 | BA39: 10.1 | BB39: 764.5 | BC39: 7.69 | BD39: 1 | BE39: 0 | BF39: 3 | BG39: 0.2
A40: 43514 | B40: NPB | C40: FB250 | E40: 1 | F40: 0 | G40: 0 | H40: 1 | I40: 0 | J40: =P40+O40+N40+M40+L40+K40 -> 0 | K40: 0 | L40: 0 | M40: 0 | N40: 0 | O40: 0 | P40: 0 | Q40: 0 | R40: =G40+S40 -> 0 | S40: 0 | T40: =U40+V40+W40 -> 0 | U40: 0 | V40: 0 | W40: 0 | X40: 0 | Y40: 0 | Z40: =SUM(AA40:AI40) -> 1 | AA40: 0 | AB40: 0 | AC40: 0 | AD40: 0 | AE40: 0 | AF40: 0 | AG40: 1 | AH40: 0 | AI40: 0 | AJ40: 0 | AK40: 0 | AL40: 0 | AM40: 0 | AN40: 0 | AO40: 0 | AP40: =SUM(E40:AO40)-Z40-J40-T40-R40 -> 3 | AR40: 18-Feb-19 | AS40: 10:35 | AT40: NPB | AU40: 10 | AV40: YSI 2030 | AW40: 11.27 | AX40: 103.6 | AY40: 2.98 | AZ40: 1.6 | BA40: 11.3 | BB40: 765 | BC40: 7.2 | BD40: 0 | BE40: 0 | BF40: 2 | BG40: 0.25
...

Sheet 2019 Data by Type
A1: Normalized Data | E1: CORE (# X 10.98) FB250 (# / 7.5) SW1 (# / 300)
A2: Date | B2: Site | C2: Sample Type | E2: Ostracod | F2: Copepod | G2: Hemiptera: Corixidae (boatman) | H2: Cladocera | I2: Nematode | J2: Diptera - TOTAL | K2: Dipteran sp. | L2: Diptera: Chironomid | M2: Diptera: Ceratopogonidae | N2: Diptera: Culicidae | O2: Diptera: Ephydridae | P2: Diptera: Stratiomyidae | Q2: Amphipod | R2: Hemiptera TOTAL | S2: Hemiptera-Notonectidae | T2: Annelida TOTAL | U2: Annelida Sp. | V2: Annelida: Oligochaete | W2: Annelida: Polychaete | X2: Ephemeroptera Sp. | Y2: Odonate | Z2: Coleoptera - TOTAL | AA2: Coleoptera sp. | AB2: Coleoptera: Dytiscidae | AC2: Coleoptera: Dytiscidae: Liodessus affinis | AD2: Coleoptera: Dytiscidae: Agabus | AE2: Coleoptera: Dytiscidae: Colymbetinae | AF2: Coleoptera: Curculionidae (Weavil) | AG2: Coleoptera - Hydrophilidae | AH2: Coleoperta Hydraenidae | AI2: Coleoptera- Gyrindae- Gyrinini | AJ2: Tipulidae Larva | AK2: Arachnida: Acari (mite) | AL2: Trichoptera Sp. | AM2: Collembola (Springtail) | AN2: Gastropod - snail | AO2: Clam Shrimp | AP2: Total # | AR2: Date | AS2: Time | AT2: Site | AU2: WQ Measurement Depth (cm) | AV2: Sample Type | AW2: Dissolved Oxygen (mg/L) | AX2: Dissolved Oxygen (%) | AY2: Conductivity-specific (mS/cm) | AZ2: Salinity (ppt) | BA2: Temperature (C) | BB2: AtmosphPressure (mmHg) | BC2: pH | BD2: No. Tadpoles | BE2: No. Fish | BF2: Sampled Width (m) | BG2: Max Invertebrate Sampled Depth (m) | BH2: Comments
A3: 43492 | B3: VWCB6 | C3: CORE | E3: 2 | F3: 0 | G3: 0 | H3: 0 | I3: 94 | J3: =P3+O3+N3+M3+L3+K3 -> 0 | K3: 0 | L3: 0 | M3: 0 | N3: 0 | O3: 0 | P3: 0 | Q3: 0 | R3: =G3+S3 -> 0 | S3: 0 | T3: =U3+V3+W3 -> 0 | U3: 0 | V3: 0 | W3: 0 | X3: 0 | Y3: 0 | Z3: =SUM(AA3:AI3) -> 0 | AA3: 0 | AB3: 0 | AC3: 0 | AD3: 0 | AE3: 0 | AF3: 0 | AG3: 0 | AH3: 0 | AI3: 0 | AJ3: 0 | AK3: 0 | AL3: 0 | AM3: 0 | AN3: 0 | AO3: 0 | AP3: =SUM(E3:AO3)-Z3-J3-T3-R3 -> 96 | AR3: 43492 | AS3: 0.60416667 | AT3: VWCB6 | AU3: 10 | AV3: YSI 2030 | AW3: 9.74 | AX3: 109.4 | AY3: 0.168 | AZ3: 0.1 | BA3: 21.2 | BB3: 762 | BC3: 8.32 | BD3: 13 | BE3: 0 | BF3: 14 | BG3: 0.33
A4: 43492 | B4: VDSN | C4: CORE | E4: 0 | F4: 0 | G4: 0 | H4: 1 | I4: 0 | J4: =P4+O4+N4+M4+L4+K4 -> 0 | K4: 0 | L4: 0 | M4: 0 | N4: 0 | O4: 0 | P4: 0 | Q4: 0 | R4: =G4+S4 -> 0 | S4: 0 | T4: =U4+V4+W4 -> 0 | U4: 0 | V4: 0 | W4: 0 | X4: 0 | Y4: 0 | Z4: =SUM(AA4:AI4) -> 0 | AA4: 0 | AB4: 0 | AC4: 0 | AD4: 0 | AE4: 0 | AF4: 0 | AG4: 0 | AH4: 0 | AI4: 0 | AJ4: 0 | AK4: 0 | AL4: 0 | AM4: 0 | AN4: 0 | AO4: 0 | AP4: =SUM(E4:AO4)-Z4-J4-T4-R4 -> 1 | AR4: 43492 | AS4: 0.65972222 | AT4: VDSN | AU4: 10 | AV4: YSI 2030 | AW4: 15.76 | AX4: 182.8 | AY4: 0.2043 | AZ4: 0.1 | BA4: 22.7 | BB4: 762.8 | BC4: 7.91 | BD4: 20 | BE4: 0 | BF4: 12.1 | BG4: 0.15
A5: 43493 | B5: VP1 | C5: CORE | E5: 0 | F5: 0 | G5: 0 | H5: 0 | I5: 0 | J5: =P5+O5+N5+M5+L5+K5 -> 0 | K5: 0 | L5: 0 | M5: 0 | N5: 0 | O5: 0 | P5: 0 | Q5: 0 | R5: =G5+S5 -> 0 | S5: 0 | T5: =U5+V5+W5 -> 0 | U5: 0 | V5: 0 | W5: 0 | X5: 0 | Y5: 0 | Z5: =SUM(AA5:AI5) -> 0 | AA5: 0 | AB5: 0 | AC5: 0 | AD5: 0 | AE5: 0 | AF5: 0 | AG5: 0 | AH5: 0 | AI5: 0 | AJ5: 0 | AK5: 0 | AL5: 0 | AM5: 1 | AN5: 0 | AO5: 0 | AP5: =SUM(E5:AO5)-Z5-J5-T5-R5 -> 1 | AR5: 43493 | AS5: 0.63541667 | AT5: CVP1 | AU5: 10 | AV5: YSI 2030 | AW5: 13.9 | AX5: 150 | AY5: 0.095 | AZ5: 0 | BA5: 18.8 | BB5: 760.8 | BC5: 9 | BD5: 74 | BE5: 0 | BF5: 13 | BG5: 0.33
A6: 43495 | B6: VNVP4 | C6: CORE | E6: 1 | F6: 0 | G6: 0 | H6: 9 | I6: 0 | J6: =P6+O6+N6+M6+L6+K6 -> 7 | K6: 0 | L6: 7 | M6: 0 | N6: 0 | O6: 0 | P6: 0 | Q6: 0 | R6: =G6+S6 -> 0 | S6: 0 | T6: =U6+V6+W6 -> 0 | U6: 0 | V6: 0 | W6: 0 | X6: 0 | Y6: 0 | Z6: =SUM(AA6:AI6) -> 0 | AA6: 0 | AB6: 0 | AC6: 0 | AD6: 0 | AE6: 0 | AF6: 0 | AG6: 0 | AH6: 0 | AI6: 0 | AJ6: 0 | AK6: 0 | AL6: 0 | AM6: 0 | AN6: 0 | AO6: 0 | AP6: =SUM(E6:AO6)-Z6-J6-T6-R6 -> 17 | AR6: 43495 | AS6: 0.47916667 | AT6: NVP4 | AU6: 10 | AV6: YSI 2030 | AW6: 8.181 | AX6: 86.5 | AY6: 0.32 | AZ6: 0.2 | BA6: 18 | BB6: 760 | BC6: 8.51 | BD6: 3 | BE6: 0 | BF6: 17 | BG6: 0.3
A7: 43503 | B7: VNVP2 | C7: CORE | E7: 7 | F7: 0 | G7: 0 | H7: 40 | I7: 0 | J7: =P7+O7+N7+M7+L7+K7 -> 6 | K7: 0 | L7: 6 | M7: 0 | N7: 0 | O7: 0 | P7: 0 | Q7: 0 | R7: =G7+S7 -> 0 | S7: 0 | T7: =U7+V7+W7 -> 0 | U7: 0 | V7: 0 | W7: 0 | X7: 0 | Y7: 0 | Z7: =SUM(AA7:AI7) -> 1 | AA7: 0 | AB7: 1 | AC7: 0 | AD7: 0 | AE7: 0 | AF7: 0 | AG7: 0 | AH7: 0 | AI7: 0 | AJ7: 0 | AK7: 0 | AL7: 0 | AM7: 0 | AN7: 0 | AO7: 0 | AP7: =SUM(E7:AO7)-Z7-J7-T7-R7 -> 54 | AR7: 7-Feb-19 | AS7: 11:50 | AT7: NVP2 | AU7: 10 | AV7: YSI 2030 | AW7: 10.3 | AX7: 101 | AY7: 0.39 | AZ7: 0.2 | BA7: 15.3 | BB7: 768.7 | BC7: 7.6 | BD7: 1 | BE7: - | BF7: 32 | BG7: 0.5
A8: 43504 | B8: VNVP10 | C8: CORE | E8: 1 | F8: 1 | G8: 0 | H8: 3 | I8: 1 | J8: =P8+O8+N8+M8+L8+K8 -> 5 | K8: 0 | L8: 5 | M8: 0 | N8: 0 | O8: 0 | P8: 0 | Q8: 0 | R8: =G8+S8 -> 0 | S8: 0 | T8: =U8+V8+W8 -> 0 | U8: 0 | V8: 0 | W8: 0 | X8: 0 | Y8: 0 | Z8: =SUM(AA8:AI8) -> 0 | AA8: 0 | AB8: 0 | AC8: 0 | AD8: 0 | AE8: 0 | AF8: 0 | AG8: 0 | AH8: 0 | AI8: 0 | AJ8: 0 | AK8: 0 | AL8: 0 | AM8: 0 | AN8: 0 | AO8: 0 | AP8: =SUM(E8:AO8)-Z8-J8-T8-R8 -> 11 | AR8: 8-Feb-19 | AS8: 14:10 | AT8: NVP10 | AU8: 10 | AV8: YSI 2030 | AW8: 8.79 | AX8: 95.8 | AY8: 0.0755 | AZ8: 0 | BA8: 19.5 | BB8: 762.6 | BC8: 7.5 | BD8: 18 | BE8: 0 | BF8: 13 | BG8: 0.28
A9: 43507 | B9: VCC7 | C9: CORE | E9: 0 | F9: 0 | G9: 0 | H9: 4 | I9: 2 | J9: =P9+O9+N9+M9+L9+K9 -> 0 | K9: 0 | L9: 0 | M9: 0 | N9: 0 | O9: 0 | P9: 0 | Q9: 0 | R9: =G9+S9 -> 0 | S9: 0 | T9: =U9+V9+W9 -> 2 | U9: 0 | V9: 2 | W9: 0 | X9: 0 | Y9: 0 | Z9: =SUM(AA9:AI9) -> 0 | AA9: 0 | AB9: 0 | AC9: 0 | AD9: 0 | AE9: 0 | AF9: 0 | AG9: 0 | AH9: 0 | AI9: 0 | AJ9: 0 | AK9: 0 | AL9: 0 | AM9: 0 | AN9: 0 | AO9: 0 | AP9: =SUM(E9:AO9)-Z9-J9-T9-R9 -> 8 | AR9: 11-Feb-19 | AS9: 15:35 | AT9: VM7 | AU9: 10 | AV9: YSI 2030 | AW9: 15.87 | AX9: 168.3 | AY9: 0.158 | AZ9: 0.1 | BA9: 18.2 | BB9: 764.7 | BC9: 8.8 | BD9: 7 | BE9: - | BF9: 8 | BG9: 0.27
A10: 43507 | B10: VM7 | C10: CORE | E10: 4 | F10: 0 | G10: 0 | H10: 16 | I10: 0 | J10: =P10+O10+N10+M10+L10+K10 -> 0 | K10: 0 | L10: 0 | M10: 0 | N10: 0 | O10: 0 | P10: 0 | Q10: 0 | R10: =G10+S10 -> 0 | S10: 0 | T10: =U10+V10+W10 -> 0 | U10: 0 | V10: 0 | W10: 0 | X10: 0 | Y10: 0 | Z10: =SUM(AA10:AI10) -> 0 | AA10: 0 | AB10: 0 | AC10: 0 | AD10: 0 | AE10: 0 | AF10: 0 | AG10: 0 | AH10: 0 | AI10: 0 | AJ10: 0 | AK10: 0 | AL10: 0 | AM10: 3 | AN10: 0 | AO10: 0 | AP10: =SUM(E10:AO10)-Z10-J10-T10-R10 -> 23 | AR10: 11-Feb-19 | AS10: 15:35 | AT10: VM7 | AU10: 10 | AV10: YSI 2030 | AW10: 15.87 | AX10: 168.3 | AY10: 0.158 | AZ10: 0.1 | BA10: 18.2 | BB10: 764.7 | BC10: 8.8 | BD10: 7 | BE10: - | BF10: 8 | BG10: 0.27
A11: 43507 | B11: VOW1 | C11: CORE | E11: 0 | F11: 0 | G11: 0 | H11: 1 | I11: 0 | J11: =P11+O11+N11+M11+L11+K11 -> 0 | K11: 0 | L11: 0 | M11: 0 | N11: 0 | O11: 0 | P11: 0 | Q11: 0 | R11: =G11+S11 -> 0 | S11: 0 | T11: =U11+V11+W11 -> 0 | U11: 0 | V11: 0 | W11: 0 | X11: 0 | Y11: 0 | Z11: =SUM(AA11:AI11) -> 0 | AA11: 0 | AB11: 0 | AC11: 0 | AD11: 0 | AE11: 0 | AF11: 0 | AG11: 0 | AH11: 0 | AI11: 0 | AJ11: 0 | AK11: 0 | AL11: 0 | AM11: 0 | AN11: 0 | AO11: 0 | AP11: =SUM(E11:AO11)-Z11-J11-T11-R11 -> 1 | AR11: 11-Feb19 | AS11: 10:50 | AT11: VOW1 | AU11: 10 | AV11: YSI 2030 | AW11: 5.74 | AX11: 50.1 | AY11: 0.03 | AZ11: 0 | BA11: 9.3 | BB11: 766 | BC11: 6.9 | BD11: 7 | BE11: 0 | BF11: 30 | BG11: 0.42
A12: 43531 | B12: VMMesa | C12: CORE | E12: 0 | F12: 0 | G12: 0 | H12: 0 | I12: 4 | J12: =P12+O12+N12+M12+L12+K12 -> 0 | K12: 0 | L12: 0 | M12: 0 | N12: 0 | O12: 0 | P12: 0 | Q12: 0 | R12: =G12+S12 -> 0 | S12: 0 | T12: =U12+V12+W12 -> 0 | U12: 0 | V12: 0 | W12: 0 | X12: 0 | Y12: 0 | Z12: =SUM(AA12:AI12) -> 0 | AA12: 0 | AB12: 0 | AC12: 0 | AD12: 0 | AE12: 0 | AF12: 0 | AG12: 0 | AH12: 0 | AI12: 0 | AJ12: 0 | AK12: 0 | AL12: 0 | AM12: 0 | AN12: 0 | AO12: 0 | AP12: =SUM(E12:AO12)-Z12-J12-T12-R12 -> 4 | AR12: 43531 | AS12: 0.35625 | AT12: VMM | AU12: 10 | AV12: YSI 2030 | AW12: 2.54 | AX12: 22.8 | AY12: 0.154 | AZ12: 0.1 | BA12: 12.1 | BD12: 4 | BE12: 0 | BG12: 0.3 | BH12: No barametric pressure or Ph data recorded
A13: 43563 | B13: VP1 | C13: CORE | E13: 87 | F13: 0 | G13: 0 | H13: 10 | I13: 0 | J13: =P13+O13+N13+M13+L13+K13 -> 0 | K13: 0 | L13: 0 | M13: 0 | N13: 0 | O13: 0 | P13: 0 | Q13: 0 | R13: =G13+S13 -> 0 | S13: 0 | T13: =U13+V13+W13 -> 0 | U13: 0 | V13: 0 | W13: 0 | X13: 0 | Y13: 0 | Z13: =SUM(AA13:AI13) -> 0 | AA13: 0 | AB13: 0 | AC13: 0 | AD13: 0 | AE13: 0 | AF13: 0 | AG13: 0 | AH13: 0 | AI13: 0 | AJ13: 0 | AK13: 0 | AL13: 0 | AM13: 0 | AN13: 0 | AO13: 0 | AP13: =SUM(E13:AO13)-Z13-J13-T13-R13 -> 97 | AR13: 43563 | AS13: 0.45833333 | AT13: VP1 | AU13: 10 | AV13: YSI 2030 | AW13: 8.97 | AX13: 107.5 | AY13: 0.162 | AZ13: 0.1 | BA13: 24.5 | BB13: 762.7 | BC13: 6.3 | BD13: 1 | BE13: 0 | BF13: 2 | BG13: 0.43
A14: 43564 | B14: NPB | C14: CORE | E14: 15 | F14: 113 | G14: 0 | H14: 31 | I14: 4 | J14: =P14+O14+N14+M14+L14+K14 -> 0 | K14: 0 | L14: 0 | M14: 0 | N14: 0 | O14: 0 | P14: 0 | Q14: 0 | R14: =G14+S14 -> 0 | S14: 0 | T14: =U14+V14+W14 -> 0 | U14: 0 | V14: 0 | W14: 0 | X14: 0 | Y14: 0 | Z14: =SUM(AA14:AI14) -> 0 | AA14: 0 | AB14: 0 | AC14: 0 | AD14: 0 | AE14: 0 | AF14: 0 | AG14: 0 | AH14: 0 | AI14: 0 | AJ14: 0 | AK14: 0 | AL14: 0 | AM14: 0 | AN14: 0 | AO14: 0 | AP14: =SUM(E14:AO14)-Z14-J14-T14-R14 -> 163 | AR14: 43564 | AS14: 0.4375 | AT14: NPB | AU14: 10 | AV14: YSI 2030 | AW14: 10.65 | AX14: 130.7 | AY14: 23.13 | AZ14: 14 | BA14: 21.4 | BB14: 762.6 | BC14: 7.65 | BD14: 0 | BE14: 0 | BF14: - | BG14: -
A15: 43564 | B15: NWP | C15: CORE | E15: 158 | F15: 7 | G15: 0 | H15: 11 | I15: 0 | J15: =P15+O15+N15+M15+L15+K15 -> 0 | K15: 0 | L15: 0 | M15: 0 | N15: 0 | O15: 0 | P15: 0 | Q15: 0 | R15: =G15+S15 -> 0 | S15: 0 | T15: =U15+V15+W15 -> 16 | U15: 0 | V15: 16 | W15: 0 | X15: 0 | Y15: 0 | Z15: =SUM(AA15:AI15) -> 0 | AA15: 0 | AB15: 0 | AC15: 0 | AD15: 0 | AE15: 0 | AF15: 0 | AG15: 0 | AH15: 0 | AI15: 0 | AJ15: 0 | AK15: 0 | AL15: 0 | AM15: 0 | AN15: 7 | AO15: 0 | AP15: =SUM(E15:AO15)-Z15-J15-T15-R15 -> 199 | AR15: 43564 | AS15: 0.44791667 | AT15: NWP | AU15: 10 | AV15: YSI 2030 | AW15: 9.2 | AX15: 102 | AY15: 1.81 | AZ15: 0.9 | BA15: 20.4 | BB15: 762.5 | BC15: 6.5 | BD15: 0 | BE15: 0 | BF15: 3 | BG15: 0.61
A16: 43565 | B16: NEC | C16: CORE | E16: 10 | F16: 23 | G16: 0 | H16: 0 | I16: 0 | J16: =P16+O16+N16+M16+L16+K16 -> 0 | K16: 0 | L16: 0 | M16: 0 | N16: 0 | O16: 0 | P16: 0 | Q16: 0 | R16: =G16+S16 -> 0 | S16: 0 | T16: =U16+V16+W16 -> 9 | U16: 0 | V16: 9 | W16: 0 | X16: 0 | Y16: 0 | Z16: =SUM(AA16:AI16) -> 0 | AA16: 0 | AB16: 0 | AC16: 0 | AD16: 0 | AE16: 0 | AF16: 0 | AG16: 0 | AH16: 0 | AI16: 0 | AJ16: 0 | AK16: 0 | AL16: 0 | AM16: 0 | AN16: 0 | AO16: 0 | AP16: =SUM(E16:AO16)-Z16-J16-T16-R16 -> 42 | AR16: 43565 | AS16: 0.75347222 | AT16: NEC | AU16: 10 | AV16: YSI 2030 | AW16: 10.4 | AX16: 134 | AY16: 43.03 | AZ16: 27.8 | BA16: 22.3 | BB16: 763.3 | BC16: 7.82 | BD16: - | BE16: - | BF16: - | BG16: -
A17: 43565 | B17: NMC | C17: CORE | E17: 3 | F17: 10 | G17: 1 | H17: 0 | I17: 0 | J17: =P17+O17+N17+M17+L17+K17 -> 0 | K17: 0 | L17: 0 | M17: 0 | N17: 0 | O17: 0 | P17: 0 | Q17: 0 | R17: =G17+S17 -> 1 | S17: 0 | T17: =U17+V17+W17 -> 65 | U17: 0 | V17: 64 | W17: 1 | X17: 0 | Y17: 0 | Z17: =SUM(AA17:AI17) -> 0 | AA17: 0 | AB17: 0 | AC17: 0 | AD17: 0 | AE17: 0 | AF17: 0 | AG17: 0 | AH17: 0 | AI17: 0 | AJ17: 0 | AK17: 0 | AL17: 0 | AM17: 0 | AN17: 0 | AO17: 0 | AP17: =SUM(E17:AO17)-Z17-J17-T17-R17 -> 79 | AR17: 43565 | AS17: - | AT17: NMC | AU17: 10 | AV17: YSI 2030 | AW17: 11.6 | AX17: 154 | AY17: 42.35 | AZ17: 26.7 | BA17: 21.3 | BB17: 763.3 | BC17: 7.77 | BD17: - | BE17: - | BF17: - | BG17: -
A18: 43565 | B18: VCC7 | C18: CORE-a+b | E18: 0 | F18: 0 | G18: 0 | H18: 15 | I18: 0 | J18: =P18+O18+N18+M18+L18+K18 -> 1 | K18: 0 | L18: 1 | M18: 0 | N18: 0 | O18: 0 | P18: 0 | Q18: 0 | R18: =G18+S18 -> 0 | S18: 0 | T18: =U18+V18+W18 -> 0 | U18: 0 | V18: 0 | W18: 0 | X18: 0 | Y18: 0 | Z18: =SUM(AA18:AI18) -> 0 | AA18: 0 | AB18: 0 | AC18: 0 | AD18: 0 | AE18: 0 | AF18: 0 | AG18: 0 | AH18: 0 | AI18: 0 | AJ18: 0 | AK18: 0 | AL18: 0 | AM18: 0 | AN18: 0 | AO18: 0 | AP18: =SUM(E18:AO18)-Z18-J18-T18-R18 -> 16 | AR18: 43565 | AS18: 0.45833333 | AT18: VCC7 | AU18: 5 | AV18: YSI 2030 | AW18: 8.4 | AX18: 113 | AY18: 0.0003 | AZ18: 0 | BA18: 32.8 | BB18: 761.6 | BC18: 6.8 | BD18: 0 | BE18: 0 | BF18: 0.05 | BG18: 0.05
A19: 43565 | B19: VDSN | C19: CORE-a+b | E19: 153 | F19: 9 | G19: 0 | H19: 196 | I19: 33 | J19: =P19+O19+N19+M19+L19+K19 -> 26 | K19: 1 | L19: 25 | M19: 0 | N19: 0 | O19: 0 | P19: 0 | Q19: 0 | R19: =G19+S19 -> 0 | S19: 0 | T19: =U19+V19+W19 -> 0 | U19: 0 | V19: 0 | W19: 0 | X19: 0 | Y19: 0 | Z19: =SUM(AA19:AI19) -> 0 | AA19: 0 | AB19: 0 | AC19: 0 | AD19: 0 | AE19: 0 | AF19: 0 | AG19: 0 | AH19: 0 | AI19: 0 | AJ19: 0 | AK19: 0 | AL19: 0 | AM19: 0 | AN19: 0 | AO19: 0 | AP19: =SUM(E19:AO19)-Z19-J19-T19-R19 -> 417 | AR19: 43565 | AS19: 0.55902778 | AT19: VDSN | AU19: 10 | AV19: YSI 2030 | AW19: 3.9 | AX19: 45 | AY19: 0.076 | AZ19: 0 | BA19: 23.5 | BB19: 761.5 | BC19: 6.1 | BD19: 0 | BE19: 0 | BF19: 2 | BG19: 0.19
A20: 43566 | B20: CUL1 | C20: CORE | E20: 10 | F20: 52 | G20: 1 | H20: 0 | I20: 0 | J20: =P20+O20+N20+M20+L20+K20 -> 0 | K20: 0 | L20: 0 | M20: 0 | N20: 0 | O20: 0 | P20: 0 | Q20: 0 | R20: =G20+S20 -> 1 | S20: 0 | T20: =U20+V20+W20 -> 86 | U20: 0 | V20: 86 | W20: 0 | X20: 0 | Y20: 0 | Z20: =SUM(AA20:AI20) -> 1 | AA20: 1 | AB20: 0 | AC20: 0 | AD20: 0 | AE20: 0 | AF20: 0 | AG20: 0 | AH20: 0 | AI20: 0 | AJ20: 0 | AK20: 0 | AL20: 0 | AM20: 0 | AN20: 0 | AO20: 0 | AP20: =SUM(E20:AO20)-Z20-J20-T20-R20 -> 150 | AR20: 43566 | AS20: - | AT20: CUL1 | AU20: 10 | AV20: YSI 2030 | AW20: 11.2 | AX20: 150 | AY20: 57.8 | AZ20: 38.6 | BA20: 18.6 | BB20: 763.2 | BC20: 7.92 | BD20: - | BE20: - | BF20: - | BG20: -
A21: 43566 | B21: MO1 | C21: CORE | E21: 7 | F21: 44 | G21: 0 | H21: 0 | I21: 42 | J21: =P21+O21+N21+M21+L21+K21 -> 0 | K21: 0 | L21: 0 | M21: 0 | N21: 0 | O21: 0 | P21: 0 | Q21: 0 | R21: =G21+S21 -> 0 | S21: 0 | T21: =U21+V21+W21 -> 5 | U21: 0 | V21: 0 | W21: 5 | X21: 0 | Y21: 0 | Z21: =SUM(AA21:AI21) -> 0 | AA21: 0 | AB21: 0 | AC21: 0 | AD21: 0 | AE21: 0 | AF21: 0 | AG21: 0 | AH21: 0 | AI21: 0 | AJ21: 0 | AK21: 0 | AL21: 0 | AM21: 0 | AN21: 0 | AO21: 0 | AP21: =SUM(E21:AO21)-Z21-J21-T21-R21 -> 98 | AR21: 43566 | AS21: - | AT21: MO1 | AU21: 10 | AV21: YSI 2030 | AW21: 9.5 | AX21: 115 | AY21: 44.01 | AZ21: 28.5 | BA21: 16.2 | BB21: 763.6 | BC21: 7.83 | BD21: - | BE21: - | BF21: - | BG21: -
A22: 43569 | B22: NVBR | C22: CORE | E22: 66 | F22: 3 | G22: 1 | H22: 0 | I22: 0 | J22: =P22+O22+N22+M22+L22+K22 -> 3 | K22: 0 | L22: 1 | M22: 2 | N22: 0 | O22: 0 | P22: 0 | Q22: 0 | R22: =G22+S22 -> 1 | S22: 0 | T22: =U22+V22+W22 -> 110 | U22: 0 | V22: 110 | W22: 0 | X22: 0 | Y22: 0 | Z22: =SUM(AA22:AI22) -> 1 | AA22: 1 | AB22: 0 | AC22: 0 | AD22: 0 | AE22: 0 | AF22: 0 | AG22: 0 | AH22: 0 | AI22: 0 | AJ22: 0 | AK22: 0 | AL22: 0 | AM22: 0 | AN22: 0 | AO22: 0 | AP22: =SUM(E22:AO22)-Z22-J22-T22-R22 -> 184 | AR22: 43569 | AS22: 0.53472222 | AT22: NVBR | AU22: 10 | AV22: YSI 2030 | AW22: 11.2 | AX22: 154 | AY22: 48.64 | AZ22: 31.8 | BA22: 22.1 | BB22: 761 | BC22: 7.96 | BD22: - | BE22: - | BF22: - | BG22: -
A23: 43569 | B23: VBR1 | C23: CORE | E23: 0 | F23: 9 | G23: 0 | H23: 0 | I23: 0 | J23: =P23+O23+N23+M23+L23+K23 -> 1 | K23: 0 | L23: 0 | M23: 1 | N23: 0 | O23: 0 | P23: 0 | Q23: 0 | R23: =G23+S23 -> 0 | S23: 0 | T23: =U23+V23+W23 -> 73 | U23: 0 | V23: 73 | W23: 0 | X23: 0 | Y23: 0 | Z23: =SUM(AA23:AI23) -> 0 | AA23: 0 | AB23: 0 | AC23: 0 | AD23: 0 | AE23: 0 | AF23: 0 | AG23: 0 | AH23: 0 | AI23: 0 | AJ23: 0 | AK23: 0 | AL23: 0 | AM23: 0 | AN23: 0 | AO23: 0 | AP23: =SUM(E23:AO23)-Z23-J23-T23-R23 -> 83 | AR23: 43569 | AS23: 0.625 | AT23: VBR1 | AU23: 10 | AV23: YSI 2030 | AW23: 13.6 | AX23: 189 | AY23: 48.5 | AZ23: 31.9 | BA23: 22.1 | BB23: 761.9 | BC23: 7.94 | BD23: - | BE23: - | BF23: - | BG23: -
A24: 43573 | B24: DSP | C24: CORE | E24: 91 | F24: 0 | G24: 0 | H24: 387 | I24: 2 | J24: =P24+O24+N24+M24+L24+K24 -> 2 | K24: 0 | L24: 2 | M24: 0 | N24: 0 | O24: 0 | P24: 0 | Q24: 0 | R24: =G24+S24 -> 0 | S24: 0 | T24: =U24+V24+W24 -> 5 | U24: 0 | V24: 5 | W24: 0 | X24: 0 | Y24: 0 | Z24: =SUM(AA24:AI24) -> 0 | AA24: 0 | AB24: 0 | AC24: 0 | AD24: 0 | AE24: 0 | AF24: 0 | AG24: 0 | AH24: 0 | AI24: 0 | AJ24: 0 | AK24: 0 | AL24: 0 | AM24: 5 | AN24: 0 | AO24: 0 | AP24: =SUM(E24:AO24)-Z24-J24-T24-R24 -> 492 | AR24: 43573 | AS24: 0.4375 | AT24: DSP | AU24: 10 | AV24: YSI 2030 | AW24: 2.6 | AX24: 29 | AY24: 1.42 | AZ24: 0.7 | BA24: 20.7 | BB24: 765.2 | BC24: 6.78 | BD24: - | BE24: - | BF24: - | BG24: -
A25: 43573 | B25: NDC | C25: CORE | E25: 38 | F25: 7 | G25: 0 | H25: 56 | I25: 1 | J25: =P25+O25+N25+M25+L25+K25 -> 0 | K25: 0 | L25: 0 | M25: 0 | N25: 0 | O25: 0 | P25: 0 | Q25: 0 | R25: =G25+S25 -> 0 | S25: 0 | T25: =U25+V25+W25 -> 0 | U25: 0 | V25: 0 | W25: 0 | X25: 0 | Y25: 0 | Z25: =SUM(AA25:AI25) -> 0 | AA25: 0 | AB25: 0 | AC25: 0 | AD25: 0 | AE25: 0 | AF25: 0 | AG25: 0 | AH25: 0 | AI25: 0 | AJ25: 0 | AK25: 0 | AL25: 0 | AM25: 0 | AN25: 0 | AO25: 0 | AP25: =SUM(E25:AO25)-Z25-J25-T25-R25 -> 102 | AR25: 43573 | AS25: 0.47222222 | AT25: NDC | AU25: 2 | AV25: YSI 2030 | AW25: 11.4 | AX25: 132 | AY25: 3.064 | AZ25: 1.6 | BA25: 22.1 | BB25: 764.6 | BC25: 8.25 | BD25: 0 | BE25: 0 | BF25: 2 | BG25: 5 | BH25: Full of red water plants
A26: 43586 | B26: VNVP10 | C26: CORE | E26: 110 | F26: 0 | G26: 0 | H26: 0 | I26: 0 | J26: =P26+O26+N26+M26+L26+K26 -> 9 | K26: 0 | L26: 9 | M26: 0 | N26: 0 | O26: 0 | P26: 0 | Q26: 0 | R26: =G26+S26 -> 0 | S26: 0 | T26: =U26+V26+W26 -> 1 | U26: 0 | V26: 0 | W26: 1 | X26: 0 | Y26: 0 | Z26: =SUM(AA26:AI26) -> 0 | AA26: 0 | AB26: 0 | AC26: 0 | AD26: 0 | AE26: 0 | AF26: 0 | AG26: 0 | AH26: 0 | AI26: 0 | AJ26: 0 | AK26: 0 | AL26: 0 | AM26: 1 | AN26: 0 | AO26: 0 | AP26: =SUM(E26:AO26)-Z26-J26-T26-R26 -> 121 | AR26: 43586 | AS26: 0.66666667 | AT26: NVP10 | AU26: 10 | AV26: YSI 2030 | AW26: 9.5 | AX26: 127 | AY26: 0.72 | AZ26: 0.3 | BA26: 30.5 | BB26: 757.4 | BC26: 7.8 | BD26: 1 | BE26: 0 | BF26: 6.5 | BG26: 0,25
A27: 43586 | B27: VNVP2 | C27: CORE | E27: 152 | F27: 0 | G27: 0 | H27: 0 | I27: 2 | J27: =P27+O27+N27+M27+L27+K27 -> 0 | K27: 0 | L27: 0 | M27: 0 | N27: 0 | O27: 0 | P27: 0 | Q27: 0 | R27: =G27+S27 -> 0 | S27: 0 | T27: =U27+V27+W27 -> 0 | U27: 0 | V27: 0 | W27: 0 | X27: 0 | Y27: 0 | Z27: =SUM(AA27:AI27) -> 0 | AA27: 0 | AB27: 0 | AC27: 0 | AD27: 0 | AE27: 0 | AF27: 0 | AG27: 0 | AH27: 0 | AI27: 0 | AJ27: 0 | AK27: 0 | AL27: 0 | AM27: 0 | AN27: 0 | AO27: 0 | AP27: =SUM(E27:AO27)-Z27-J27-T27-R27 -> 154 | AR27: 43586 | AS27: 0.61458333 | AT27: NVP2 | AU27: 10 | AV27: YSI 2030 | AW27: 8 | AX27: 103 | AY27: 0.0007 | AZ27: 0 | BA27: 28.3 | BB27: 759.5 | BC27: 7.8 | BD27: 0 | BE27: 0 | BF27: 18 | BG27: 0.2
A28: 43586 | B28: VNVP4 | C28: CORE | E28: 36 | F28: 2 | G28: 0 | H28: 3 | I28: 1 | J28: =P28+O28+N28+M28+L28+K28 -> 2 | K28: 0 | L28: 2 | M28: 0 | N28: 0 | O28: 0 | P28: 0 | Q28: 0 | R28: =G28+S28 -> 0 | S28: 0 | T28: =U28+V28+W28 -> 0 | U28: 0 | V28: 0 | W28: 0 | X28: 0 | Y28: 0 | Z28: =SUM(AA28:AI28) -> 0 | AA28: 0 | AB28: 0 | AC28: 0 | AD28: 0 | AE28: 0 | AF28: 0 | AG28: 0 | AH28: 0 | AI28: 0 | AJ28: 0 | AK28: 0 | AL28: 0 | AM28: 0 | AN28: 0 | AO28: 0 | AP28: =SUM(E28:AO28)-Z28-J28-T28-R28 -> 44 | AR28: 43586 | AS28: 0.5625 | AT28: NVP4 | AU28: 5 | AV28: YSI 2030 | AW28: 15.76 | AX28: 183 | AY28: 0.204 | AZ28: 0.1 | BA28: 22.7 | BB28: 760.5 | BC28: 9.2 | BD28: 0 | BE28: 0 | BF28: 10 | BG28: 0.05 | BH28: Maximum pool depth 10 cm
A29: 43587 | B29: VM3 | C29: CORE | E29: 260 | F29: 2 | G29: 0 | H29: 1 | I29: 0 | J29: =P29+O29+N29+M29+L29+K29 -> 0 | K29: 0 | L29: 0 | M29: 0 | N29: 0 | O29: 0 | P29: 0 | Q29: 0 | R29: =G29+S29 -> 0 | S29: 0 | T29: =U29+V29+W29 -> 0 | U29: 0 | V29: 0 | W29: 0 | X29: 0 | Y29: 0 | Z29: =SUM(AA29:AI29) -> 0 | AA29: 0 | AB29: 0 | AC29: 0 | AD29: 0 | AE29: 0 | AF29: 0 | AG29: 0 | AH29: 0 | AI29: 0 | AJ29: 0 | AK29: 0 | AL29: 0 | AM29: 0 | AN29: 0 | AO29: 0 | AP29: =SUM(E29:AO29)-Z29-J29-T29-R29 -> 263 | AR29: 43587 | AS29: 0.625 | AT29: VM3 | AU29: 10 | AV29: YSI 2030 | AW29: 8.5 | AX29: 109 | AY29: 0.329 | AZ29: 0.2 | BA29: 28.1 | BB29: 759.9 | BC29: 7.5 | BD29: 1 | BE29: 0 | BF29: 8 | BG29: 0.1
A30: 43643 | B30: MO1 | C30: CORE | E30: 12 | F30: 61 | G30: 0 | H30: 0 | I30: 0 | J30: =P30+O30+N30+M30+L30+K30 -> 8 | K30: 0 | L30: 7 | M30: 0 | N30: 0 | O30: 1 | P30: 0 | Q30: 4 | R30: =G30+S30 -> 0 | S30: 0 | T30: =U30+V30+W30 -> 1 | U30: 1 | V30: 0 | W30: 0 | X30: 0 | Y30: 0 | Z30: =SUM(AA30:AI30) -> 0 | AA30: 0 | AB30: 0 | AC30: 0 | AD30: 0 | AE30: 0 | AF30: 0 | AG30: 0 | AH30: 0 | AI30: 0 | AJ30: 0 | AK30: 0 | AL30: 0 | AM30: 0 | AN30: 0 | AO30: 0 | AP30: =SUM(E30:AO30)-Z30-J30-T30-R30 -> 86 | AR30: 43643 | AS30: 0.60416667 | AT30: MO1 | AU30: 10 | AV30: YSI 2030 | AW30: 15.1 | AX30: 214 | AY30: 39.6 | AZ30: 25.3 | BA30: 25.8 | BB30: 761 | BC30: 8.6 | BD30: 0 | BE30: 0 | BF30: 2 | BG30: 0.15
A31: 43643 | B31: NDC | C31: CORE | E31: 13 | F31: 5 | G31: 0 | H31: 1 | I31: 22 | J31: =P31+O31+N31+M31+L31+K31 -> 1 | K31: 0 | L31: 1 | M31: 0 | N31: 0 | O31: 0 | P31: 0 | Q31: 0 | R31: =G31+S31 -> 0 | S31: 0 | T31: =U31+V31+W31 -> 0 | U31: 0 | V31: 0 | W31: 0 | X31: 0 | Y31: 0 | Z31: =SUM(AA31:AI31) -> 0 | AA31: 0 | AB31: 0 | AC31: 0 | AD31: 0 | AE31: 0 | AF31: 0 | AG31: 0 | AH31: 0 | AI31: 0 | AJ31: 0 | AK31: 0 | AL31: 0 | AM31: 0 | AN31: 4 | AO31: 0 | AP31: =SUM(E31:AO31)-Z31-J31-T31-R31 -> 46 | AR31: 43643 | AS31: 0.46875 | AT31: NDC | AU31: 5 | AV31: YSI 2030 | AW31: 3.8 | AX31: 42 | AY31: 5.61 | AZ31: 3.1 | BA31: 20.6 | BB31: 763.1 | BC31: 6.5 | BD31: 0 | BE31: 0 | BF31: 1.5 | BG31: 0.07 | BH31: Covered with red algae-photos
A32: 43643 | B32: NWP | C32: CORE | E32: 4 | F32: 0 | G32: 0 | H32: 15 | I32: 0 | J32: =P32+O32+N32+M32+L32+K32 -> 0 | K32: 0 | L32: 0 | M32: 0 | N32: 0 | O32: 0 | P32: 0 | Q32: 0 | R32: =G32+S32 -> 0 | S32: 0 | T32: =U32+V32+W32 -> 0 | U32: 0 | V32: 0 | W32: 0 | X32: 0 | Y32: 0 | Z32: =SUM(AA32:AI32) -> 0 | AA32: 0 | AB32: 0 | AC32: 0 | AD32: 0 | AE32: 0 | AF32: 0 | AG32: 0 | AH32: 0 | AI32: 0 | AJ32: 0 | AK32: 0 | AL32: 0 | AM32: 0 | AN32: 0 | AO32: 0 | AP32: =SUM(E32:AO32)-Z32-J32-T32-R32 -> 19 | AR32: 43643 | AS32: 0.49305556 | AT32: NWP | AU32: 10 | AV32: YSI 2030 | AW32: 13.1 | AX32: 161 | AY32: 2.39 | AZ32: 1.2 | BA32: 24.5 | BB32: 762.8 | BC32: 8.8 | BD32: 0 | BE32: 0 | BF32: 2 | BG32: 0.15
A33: 43647 | B33: NPB | C33: CORE | E33: 0 | F33: 0 | G33: 2 | I33: 1 | J33: =P33+O33+N33+M33+L33+K33 -> 0 | K33: 0 | L33: 0 | M33: 0 | N33: 0 | O33: 0 | P33: 0 | Q33: 0 | R33: =G33+S33 -> 2 | S33: 0 | T33: =U33+V33+W33 -> 0 | U33: 0 | V33: 0 | W33: 0 | X33: 0 | Y33: 0 | Z33: =SUM(AA33:AI33) -> 0 | AA33: 0 | AB33: 0 | AC33: 0 | AD33: 0 | AE33: 0 | AF33: 0 | AG33: 0 | AH33: 0 | AI33: 0 | AJ33: 0 | AK33: 0 | AL33: 0 | AM33: 0 | AN33: 0 | AO33: 0 | AP33: =SUM(E33:AO33)-Z33-J33-T33-R33 -> 3 | AR33: 43647 | AS33: 0.39583333 | AT33: NPB | AU33: 10 | AV33: YSI 2030 | AW33: 7.8 | AX33: 101 | AY33: 13.69 | AZ33: 7.9 | BA33: 26.2 | BB33: 759.2 | BC33: 7.5 | BD33: 0 | BE33: 1 | BF33: 2.5 | BG33: 0.2
A34: 43648 | B34: NVBR | C34: CORE | E34: 14 | F34: 0 | G34: 0 | H34: 0 | I34: 0 | J34: =P34+O34+N34+M34+L34+K34 -> 0 | K34: 0 | L34: 0 | M34: 0 | N34: 0 | O34: 0 | P34: 0 | Q34: 0 | R34: =G34+S34 -> 0 | S34: 0 | T34: =U34+V34+W34 -> 0 | U34: 0 | V34: 0 | W34: 0 | X34: 0 | Y34: 0 | Z34: =SUM(AA34:AI34) -> 0 | AA34: 0 | AB34: 0 | AC34: 0 | AD34: 0 | AE34: 0 | AF34: 0 | AG34: 0 | AH34: 0 | AI34: 0 | AJ34: 0 | AK34: 0 | AL34: 0 | AM34: 0 | AN34: 0 | AO34: 0 | AP34: =SUM(E34:AO34)-Z34-J34-T34-R34 -> 14 | AR34: 43648 | AS34: 0.66666667 | AT34: NVBR | AU34: 10 | AV34: YSI 2030 | AW34: 13.2 | AX34: 195 | AY34: 32.2 | AZ34: 20 | BA34: 29.7 | BB34: 758 | BC34: 8.9 | BD34: 0 | BE34: 0 | BF34: 3 | BG34: 0.4
A35: 43648 | B35: VBR1 | C35: CORE | E35: 105 | F35: 0 | G35: 0 | H35: 0 | I35: 0 | J35: =P35+O35+N35+M35+L35+K35 -> 0 | K35: 0 | L35: 0 | M35: 0 | N35: 0 | O35: 0 | P35: 0 | Q35: 0 | R35: =G35+S35 -> 0 | S35: 0 | T35: =U35+V35+W35 -> 1 | U35: 1 | V35: 0 | W35: 0 | X35: 0 | Y35: 0 | Z35: =SUM(AA35:AI35) -> 0 | AA35: 0 | AB35: 0 | AC35: 0 | AD35: 0 | AE35: 0 | AF35: 0 | AG35: 0 | AH35: 0 | AI35: 0 | AJ35: 0 | AK35: 0 | AL35: 0 | AM35: 0 | AN35: 0 | AO35: 0 | AP35: =SUM(E35:AO35)-Z35-J35-T35-R35 -> 106 | AR35: 43648 | AS35: 0.70833333 | AT35: VBR1 | AU35: 10 | AV35: YSI 2030 | AW35: 12.8 | AX35: 193 | AY35: 33.6 | AZ35: 21 | BA35: 29.3 | BB35: 757.2 | BC35: 8.9 | BD35: 0 | BE35: 0 | BF35: 2 | BG35: 0.4
A36: 43657 | B36: DSP | C36: CORE | E36: 1 | F36: 0 | G36: 1 | H36: 2 | I36: 0 | J36: =P36+O36+N36+M36+L36+K36 -> 0 | K36: 0 | L36: 0 | M36: 0 | N36: 0 | O36: 0 | P36: 0 | Q36: 0 | R36: =G36+S36 -> 1 | S36: 0 | T36: =U36+V36+W36 -> 0 | U36: 0 | V36: 0 | W36: 0 | X36: 0 | Y36: 0 | Z36: =SUM(AA36:AI36) -> 0 | AA36: 0 | AB36: 0 | AC36: 0 | AD36: 0 | AE36: 0 | AF36: 0 | AG36: 0 | AH36: 0 | AI36: 0 | AJ36: 0 | AK36: 0 | AL36: 0 | AM36: 0 | AN36: 0 | AO36: 0 | AP36: =SUM(E36:AO36)-Z36-J36-T36-R36 -> 4 | AR36: 43657 | AS36: 0.69444444 | AT36: DSP | AU36: 10 | AV36: YSI 2030 | AW36: 7.6 | AX36: 98 | AY36: 5.13 | AZ36: 2.7 | BA36: 27.6 | BB36: 760.2 | BC36: 7.3 | BD36: 0 | BE36: 0 | BF36: 1 | BG36: 0.6
A37: 43658 | B37: CUL1 | C37: CORE | E37: 0 | F37: 0 | G37: 4 | H37: 0 | I37: 0 | J37: =P37+O37+N37+M37+L37+K37 -> 0 | K37: 0 | L37: 0 | M37: 0 | N37: 0 | O37: 0 | P37: 0 | Q37: 0 | R37: =G37+S37 -> 4 | S37: 0 | T37: =U37+V37+W37 -> 0 | U37: 0 | V37: 0 | W37: 0 | X37: 0 | Y37: 0 | Z37: =SUM(AA37:AI37) -> 0 | AA37: 0 | AB37: 0 | AC37: 0 | AD37: 0 | AE37: 0 | AF37: 0 | AG37: 0 | AH37: 0 | AI37: 0 | AJ37: 0 | AK37: 0 | AL37: 0 | AM37: 0 | AN37: 0 | AO37: 0 | AP37: =SUM(E37:AO37)-Z37-J37-T37-R37 -> 4 | AR37: 43658 | AS37: 0.32291667 | AT37: CUL1 | AU37: 5 | AV37: YSI 2030 | AW37: 0.6 | AX37: 5 | AY37: 30.41 | AZ37: 15.9 | BA37: 20.9 | BB37: 759.8 | BC37: 8 | BD37: 0 | BE37: 0 | BF37: 0.5 | BG37: 0.1
A38: 43678 | B38: NEC | C38: CORE | E38: 2 | F38: 3 | G38: 0 | H38: 0 | I38: 0 | J38: =P38+O38+N38+M38+L38+K38 -> 4 | K38: 0 | L38: 2 | M38: 0 | N38: 0 | O38: 2 | P38: 0 | Q38: 0 | R38: =G38+S38 -> 0 | S38: 0 | T38: =U38+V38+W38 -> 3 | U38: 3 | V38: 0 | W38: 0 | X38: 0 | Y38: 0 | Z38: =SUM(AA38:AI38) -> 0 | AA38: 0 | AB38: 0 | AC38: 0 | AD38: 0 | AE38: 0 | AF38: 0 | AG38: 0 | AH38: 0 | AI38: 0 | AJ38: 0 | AK38: 0 | AL38: 0 | AM38: 0 | AN38: 0 | AO38: 0 | AP38: =SUM(E38:AO38)-Z38-J38-T38-R38 -> 12 | AR38: 43678 | AS38: 0.69097222 | AT38: NEC | AU38: 10 | AV38: YSI 2030 | AW38: 12.7 | AX38: 208 | AY38: 48.54 | AZ38: 31.6 | BA38: 31.6 | BB38: 759.5 | BC38: 8.8 | BD38: 0 | BE38: 0 | BF38: 1 | BG38: 0.5
A39: 43678 | B39: NMC | C39: CORE | E39: 34 | F39: 0 | G39: 0 | H39: 0 | I39: 0 | J39: =P39+O39+N39+M39+L39+K39 -> 1 | K39: 0 | L39: 1 | M39: 0 | N39: 0 | O39: 0 | P39: 0 | Q39: 0 | R39: =G39+S39 -> 0 | S39: 0 | T39: =U39+V39+W39 -> 0 | U39: 0 | V39: 0 | W39: 0 | X39: 0 | Y39: 0 | Z39: =SUM(AA39:AI39) -> 0 | AA39: 0 | AB39: 0 | AC39: 0 | AD39: 0 | AE39: 0 | AF39: 0 | AG39: 0 | AH39: 0 | AI39: 0 | AJ39: 0 | AK39: 0 | AL39: 0 | AM39: 0 | AN39: 0 | AO39: 0 | AP39: =SUM(E39:AO39)-Z39-J39-T39-R39 -> 35 | AR39: 43678 | AS39: 0.66666667 | AT39: NMC | AU39: 10 | AV39: YSI 2030 | AW39: 6.4 | AX39: 107 | AY39: 42.32 | AZ39: 26.6 | BA39: 34.1 | BB39: 759.3 | BC39: 8.5 | BD39: 0 | BE39: 0 | BF39: 0.5 | BG39: 1
A40: 43678 | B40: NPB | C40: CORE | E40: 7 | F40: 0 | G40: 0 | H40: 0 | I40: 0 | J40: =P40+O40+N40+M40+L40+K40 -> 24 | K40: 0 | L40: 0 | M40: 0 | N40: 0 | O40: 24 | P40: 0 | Q40: 0 | R40: =G40+S40 -> 0 | S40: 0 | T40: =U40+V40+W40 -> 7 | U40: 0 | V40: 7 | W40: 0 | X40: 0 | Y40: 0 | Z40: =SUM(AA40:AI40) -> 1 | AA40: 0 | AB40: 1 | AC40: 0 | AD40: 0 | AE40: 0 | AF40: 0 | AG40: 0 | AH40: 0 | AI40: 0 | AJ40: 3 | AK40: 0 | AL40: 0 | AM40: 0 | AN40: 0 | AO40: 0 | AP40: =SUM(E40:AO40)-Z40-J40-T40-R40 -> 42 | AR40: 43678 | AS40: 0.63888889 | AT40: NPB | AU40: 10 | AV40: YSI 2030 | AW40: 13.2 | AX40: 196 | AY40: 22.33 | AZ40: 13.3 | BA40: 32.6 | BB40: 759.5 | BC40: 7.6 | BD40: 0 | BE40: 0 | BF40: 1 | BG40: 0.4
...

Sheet 2019 Normalized
